Workbook

Sheet 1.표지·요약
A1: 신OO님 보장분석 · 제안 보고서
B4: 고객 정보
B5: 성명 / 연령 / 성별 | C5: 신OO / 만 36세 / 여
B6: 분석 기준일 | C6: 2026-08-13
B7: 보고서 작성일 | C7: 2026-08-14
B8: 자료 출처 | C8: 한국신용정보원 집적 계약정보 기반 보장분석 (2026-08-13 13:37:40 조회)
B9: 담당 | C9: OOO
B11: 한눈에 보는 요약
B12: 보유 계약 | C12: =TEXT(COUNTA('2.계약현황'!B6:B8),"0")&"건 (전부 현대해상, 정상계약)" -> 3건 (전부 현대해상, 정상계약)
B13: 월 납입 보험료 | C13: ='2.계약현황'!I10 -> 119550
B14: 총 납입 보험료 (현 보험료 기준) | C14: ='2.계약현황'!J10 -> 29050800
B15: 기납입 보험료 | C15: ='2.계약현황'!K10 -> 16118610
B16: 앞으로 낼 보험료(잔여) | C16: ='2.계약현황'!L10 -> 12932190
B17: 납입 진행률 | C17: ='2.계약현황'!M10 -> 0.55484221
B19: 보장 준비상태 집계 (권장금액 설정 담보 기준)
B20: 구분 | C20: 충분 | D20: 부족 | E20: 미가입 | F20: 판정대상 합계
B21: 담보 수 | C21: =COUNTIF('3.보장분석(메인)'!$K$6:$K$200,"충분") -> 10 | D21: =COUNTIF('3.보장분석(메인)'!$K$6:$K$200,"부족") -> 10 | E21: =COUNTIF('3.보장분석(메인)'!$K$6:$K$200,"미가입") -> 20 | F21: =SUM(C21:E21) -> 40
B23: 핵심 진단 (요약)
B24: ① 지켜야 할 것 | C24: 2010년 가입 실손은 2세대(표준화 이전기)로 자기부담 10%·재가입 조건 없이 100세(2090년)까지 유지됩니다. 현행 5세대 대비 비급여 보장이 넓어 보유 계약 중 가치가 가장 높습니다. → 시트 '6.실손분석' 참고
B25: ② 가장 큰 공백 | C25: 생존 담보가 비어 있습니다. 일반암 1,000만원(권장 1억 대비 -9,000만), 뇌·심장 진단비 전 항목 미가입, 간병·치매 전 항목 미가입.
B26: ★ 2026 3대 트렌드 | C26: 보험의 무게중심이 '진단금'에서 '치료비'로 옮겨간 15년의 변화가 계약에 전혀 반영되어 있지 않습니다. ① 암 주요치료비 — 수술·항암약물·방사선 치료를 받을 때마다 반복 지급(표적항암제 연 6,000만~1억 2,000만원 대응) → 미보유. ② 순환계 주요치료비 — 검사·수술·혈전용해·ECMO·재활까지 전 과정 포괄, 부정맥·심부전까지 확대 → 미보유(진단비조차 0원). ③ 정액 수술보험금 — 5세대 실손의 비중증 비급여 축소(자기부담 30%→50%, 한도 5,000만→1,000만)로 역할이 커진 담보 → '16대질병수술 100만원' 한정형만 보유. 상세는 시트 '7.3대핵심트렌드' 참고.
B27: ③ 사망보장 편중 | C27: 상해사망 1억 6,000만원은 있으나 질병사망은 0원입니다. 36세 여성 기준 사망원인의 대부분이 질병이라는 점과 어긋납니다.
B28: ④ 운전자보험 | C28: 2017년 가입분이라 변호사선임비용의 자기부담금 50%(2026년 개정) 적용을 받지 않는 유리한 약관이지만, 교통사고처리지원금 3,000만원(권장 2억)·변호사선임비용 500만원은 현 시세 대비 크게 부족합니다.
B29: ⑤ 만기 주의 | C29: 치아보험(계약③)은 2034-10-01, 만 44세 만기입니다. 이후 치과보장과 보철치료비 200만원이 함께 소멸합니다. 자동차보험(KB다이렉트)은 2026-08-19 만기로 갱신 시점이 임박했습니다.
B31: ※ 본 보고서는 고객 요청에 따라 '현황 정리' 중심으로 작성되었습니다. 신규 가입 제안 및 예상 보험료는 포함하지 않았습니다. ※ 권장금액은 KB손해보험 보장분석 기준(기본형 37개 담보 / 표준형)을 따랐습니다. ※ 시트 '4.담보마스터'의 담보명·권장금액·코멘트를 수정하면 '3.보장분석(메인)'에 자동 반영됩니다.

Sheet 2.계약현황
A1: 계약별 현황 및 보험료 (총 / 기납입 / 잔여)
A2: 총납입·기납입·잔여 보험료는 '월보험료 × 회차'로 산출한 수식값입니다. 기준일(N3)을 바꾸면 전 시트가 자동 재계산됩니다.
M3: 기준일 → | N3: 46247
B5: 계약 | C5: 회사 / 상품명 | D5: 계약일 | E5: 만기일 | F5: 납입 주기 | G5: 납입기간 | H5: 만기연령 | I5: 월 보험료 | J5: 총 납입보험료 | K5: 기납입 보험료 | L5: 잔여 보험료 | M5: 납입 진행률 | N5: 갱신 여부 / 특이사항
B6: ① Hi1010 (종합) | C6: 현대해상 무배당하이라이프퍼펙트패키지보험(Hi1010)2종 | D6: 40535 | E6: 69755 | F6: 월납 | G6: 25년납 (~2035-12-23) | H6: 100세 만기 | I6: 56300 | J6: =$I6*25*12 -> 16890000 | K6: =$I6*MIN(25*12,DATEDIF($D6,$N$3,"m")+1) -> 10584400 | L6: =$J6-$K6 -> 6305600 | M6: =IFERROR($K6/$J6,0) -> 0.62666667 | N6: 비갱신(만기까지 확정) 주력 종합보험. 2세대 실손 포함, 100세 만기
B7: ② Hi1709 (운전자) | C7: 현대해상 무배당하이카운전자보험(Hi1709)2종기본플랜 | D7: 43059 | E7: 62417 | F7: 월납 | G7: 20년납 (~2037-11-20) | H7: 80세 만기 | I7: 12930 | J7: =$I7*20*12 -> 3103200 | K7: =$I7*MIN(20*12,DATEDIF($D7,$N$3,"m")+1) -> 1357650 | L7: =$J7-$K7 -> 1745550 | M7: =IFERROR($K7/$J7,0) -> 0.4375 | N7: 비갱신 운전자 전용. 2026년 개정 前 약관(변호사비 자기부담금 없음)
B8: ③ Hi1904 (치아) | C8: 현대해상 무배당퍼펙트치아보험(갱신형)(Hi1904)기본플랜 | D8: 43739 | E8: 49218 | F8: 월납 | G8: 15년납 (~2034-10-01) | H8: 44세 만기 | I8: 50320 | J8: =$I8*15*12 -> 9057600 | K8: =$I8*MIN(15*12,DATEDIF($D8,$N$3,"m")+1) -> 4176560 | L8: =$J8-$K8 -> 4881040 | M8: =IFERROR($K8/$J8,0) -> 0.46111111 | N8: 갱신형(보험료 인상 가능) 전기납 갱신형. 2034.10 만기 후 치과보장 소멸
C9: (계약 추가 시 이 행에 입력)
B10: 합 계 | I10: =SUM(I6:I9) -> 119550 | J10: =SUM(J6:J9) -> 29050800 | K10: =SUM(K6:K9) -> 16118610 | L10: =SUM(L6:L9) -> 12932190 | M10: =IFERROR(K10/J10,0) -> 0.55484221
B12: 산출 기준 | C12: 월보험료 × 납입 회차. 기납입 회차 = MIN(총 납입회차, 계약일부터 기준일까지 경과 개월수 + 1회).
B13: 계약③ 주의 | C13: 치아보험은 갱신형이므로 갱신 시 보험료가 오릅니다. 위 총납입·잔여 보험료는 '현재 보험료가 만기까지 유지된다'는 가정의 최소 추정치입니다. 실제 총액은 이보다 커집니다.
B14: 계약③ 만기 | C14: 2034-10-01(만 44세) 만기 = 납입만기와 동일한 전기납 구조입니다. 만기 후 치과보장은 소멸합니다.
B15: 자동차보험 | C15: KB다이렉트개인용(2025-08-19~2026-08-19)은 신용정보원 조회분으로 위 3건과 별개입니다. 시트 '9.특이사항' 참고.

Sheet 3.보장분석(메인)
A1: 신OO님 담보별 보장분석 (보장분석24 포맷 기준)
A2: 담보명·권장금액·트렌드·코멘트는 '4.담보마스터'에서, 계약별 가입금액은 '5.담보원장'에서 자동으로 가져옵니다. 금액 단위: 만원(일당은 만원/일).
C4: ↓ 계약번호(수식 참조용) | E4: 1 | F4: 2 | G4: 3
B5: 대분류 | C5: 담보명 | D5: 단위 | E5: ① Hi1010 (종합) | F5: ② Hi1709 (운전자) | G5: ③ Hi1904 (치아) | H5: 합계 (가입금액) | I5: 권장금액 (KB기준) | J5: 과부족 | K5: 준비 상태 | L5: 2026 시장통용 설계수준 | M5: 트렌드기준 과부족 | N5: 최근 담보유형 (2026년 트렌드) 비교 | O5: 특이사항 / 코멘트
B6: =IF('4.담보마스터'!C5="","",'4.담보마스터'!C5) -> 사망 | C6: =IF('4.담보마스터'!D5="","",'4.담보마스터'!D5) -> 일반(종신)사망 | D6: =IF('4.담보마스터'!E5="","",'4.담보마스터'!E5) -> 만원 | E6: =IF($C6="","",SUMIFS('5.담보원장'!$G$5:$G$68,'5.담보원장'!$F$5:$F$68,$C6,'5.담보원장'!$B$5:$B$68,E$4)) -> 0 | F6: =IF($C6="","",SUMIFS('5.담보원장'!$G$5:$G$68,'5.담보원장'!$F$5:$F$68,$C6,'5.담보원장'!$B$5:$B$68,F$4)) -> 0 | G6: =IF($C6="","",SUMIFS('5.담보원장'!$G$5:$G$68,'5.담보원장'!$F$5:$F$68,$C6,'5.담보원장'!$B$5:$B$68,G$4)) -> 0 | H6: =IF($C6="","",SUM(E6:G6)) -> 0 | I6: =IF('4.담보마스터'!F5="","",'4.담보마스터'!F5) -> 10000 | J6: =IF(OR($C6="",$I6=""),"",$H6-$I6) -> -10000 | K6: =IF($C6="","",IF($I6="","－",IF($H6=0,"미가입",IF($H6>=$I6,"충분","부족")))) -> 미가입 | L6: =IF('4.담보마스터'!G5="","",'4.담보마스터'!G5) | M6: =IF(OR($C6="",$L6=""),"",$H6-$L6) | N6: =IF('4.담보마스터'!H5="","",'4.담보마스터'!H5) -> 종신사망 자체는 정체. 사망보험금 유동화(연금·요양비 전환) 제도 도입으로 활용도 재조명 | O6: =IF('4.담보마스터'!I5="","",'4.담보마스터'!I5) -> 미가입. 손보 종합보험에는 통상 미탑재 — 필요 시 생보 종신/정기로 보완 영역
B7: =IF('4.담보마스터'!C6="","",'4.담보마스터'!C6) -> 사망 | C7: =IF('4.담보마스터'!D6="","",'4.담보마스터'!D6) -> 질병(정기)사망 | D7: =IF('4.담보마스터'!E6="","",'4.담보마스터'!E6) -> 만원 | E7: =IF($C7="","",SUMIFS('5.담보원장'!$G$5:$G$68,'5.담보원장'!$F$5:$F$68,$C7,'5.담보원장'!$B$5:$B$68,E$4)) -> 0 | F7: =IF($C7="","",SUMIFS('5.담보원장'!$G$5:$G$68,'5.담보원장'!$F$5:$F$68,$C7,'5.담보원장'!$B$5:$B$68,F$4)) -> 0 | G7: =IF($C7="","",SUMIFS('5.담보원장'!$G$5:$G$68,'5.담보원장'!$F$5:$F$68,$C7,'5.담보원장'!$B$5:$B$68,G$4)) -> 0 | H7: =IF($C7="","",SUM(E7:G7)) -> 0 | I7: =IF('4.담보마스터'!F6="","",'4.담보마스터'!F6) -> 10000 | J7: =IF(OR($C7="",$I7=""),"",$H7-$I7) -> -10000 | K7: =IF($C7="","",IF($I7="","－",IF($H7=0,"미가입",IF($H7>=$I7,"충분","부족")))) -> 미가입 | L7: =IF('4.담보마스터'!G6="","",'4.담보마스터'!G6) -> 10000 | M7: =IF(OR($C7="",$L7=""),"",$H7-$L7) -> -10000 | N7: =IF('4.담보마스터'!H6="","",'4.담보마스터'!H6) -> 80세·90세 만기 정기형 질병사망이 주류. 종신형 대비 보험료 1/3 수준 | O7: =IF('4.담보마스터'!I6="","",'4.담보마스터'!I6) -> 미가입 (권장 1억 대비 -1억). 현재 사망보장은 '상해'에만 존재
B8: =IF('4.담보마스터'!C7="","",'4.담보마스터'!C7) -> 사망 | C8: =IF('4.담보마스터'!D7="","",'4.담보마스터'!D7) -> 재해(정기)사망 | D8: =IF('4.담보마스터'!E7="","",'4.담보마스터'!E7) -> 만원 | E8: =IF($C8="","",SUMIFS('5.담보원장'!$G$5:$G$68,'5.담보원장'!$F$5:$F$68,$C8,'5.담보원장'!$B$5:$B$68,E$4)) -> 0 | F8: =IF($C8="","",SUMIFS('5.담보원장'!$G$5:$G$68,'5.담보원장'!$F$5:$F$68,$C8,'5.담보원장'!$B$5:$B$68,F$4)) -> 0 | G8: =IF($C8="","",SUMIFS('5.담보원장'!$G$5:$G$68,'5.담보원장'!$F$5:$F$68,$C8,'5.담보원장'!$B$5:$B$68,G$4)) -> 0 | H8: =IF($C8="","",SUM(E8:G8)) -> 0 | I8: =IF('4.담보마스터'!F7="","",'4.담보마스터'!F7) | J8: =IF(OR($C8="",$I8=""),"",$H8-$I8) | K8: =IF($C8="","",IF($I8="","－",IF($H8=0,"미가입",IF($H8>=$I8,"충분","부족")))) -> － | L8: =IF('4.담보마스터'!G7="","",'4.담보마스터'!G7) | M8: =IF(OR($C8="",$L8=""),"",$H8-$L8) | N8: =IF('4.담보마스터'!H7="","",'4.담보마스터'!H7) -> 생보 재해사망 개념. 손보는 '상해사망'으로 대체 표기 | O8: =IF('4.담보마스터'!I7="","",'4.담보마스터'!I7) -> 손보 계약이므로 상해사망 행으로 집계
B9: =IF('4.담보마스터'!C8="","",'4.담보마스터'!C8) -> 사망 | C9: =IF('4.담보마스터'!D8="","",'4.담보마스터'!D8) -> 상해(정기)사망 | D9: =IF('4.담보마스터'!E8="","",'4.담보마스터'!E8) -> 만원 | E9: =IF($C9="","",SUMIFS('5.담보원장'!$G$5:$G$68,'5.담보원장'!$F$5:$F$68,$C9,'5.담보원장'!$B$5:$B$68,E$4)) -> 16000 | F9: =IF($C9="","",SUMIFS('5.담보원장'!$G$5:$G$68,'5.담보원장'!$F$5:$F$68,$C9,'5.담보원장'!$B$5:$B$68,F$4)) -> 0 | G9: =IF($C9="","",SUMIFS('5.담보원장'!$G$5:$G$68,'5.담보원장'!$F$5:$F$68,$C9,'5.담보원장'!$B$5:$B$68,G$4)) -> 0 | H9: =IF($C9="","",SUM(E9:G9)) -> 16000 | I9: =IF('4.담보마스터'!F8="","",'4.담보마스터'!F8) -> 20000 | J9: =IF(OR($C9="",$I9=""),"",$H9-$I9) -> -4000 | K9: =IF($C9="","",IF($I9="","－",IF($H9=0,"미가입",IF($H9>=$I9,"충분","부족")))) -> 부족 | L9: =IF('4.담보마스터'!G8="","",'4.담보마스터'!G8) -> 20000 | M9: =IF(OR($C9="",$L9=""),"",$H9-$L9) -> -4000 | N9: =IF('4.담보마스터'!H8="","",'4.담보마스터'!H8) -> 상해사망 + 교통상해사망 + 대중교통이용중 상해사망으로 세분화 설계 | O9: =IF('4.담보마스터'!I8="","",'4.담보마스터'!I8) -> 계약① 기본계약 1,000만 + 상해사망후유장해추가 1억 5,000만 = 1억 6,000만 (권장 2억 대비 -4,000만)
B10: =IF('4.담보마스터'!C9="","",'4.담보마스터'!C9) -> 수술·입원 | C10: =IF('4.담보마스터'!D9="","",'4.담보마스터'!D9) -> 수술비-질병(1~5종) | D10: =IF('4.담보마스터'!E9="","",'4.담보마스터'!E9) -> 만원 | E10: =IF($C10="","",SUMIFS('5.담보원장'!$G$5:$G$68,'5.담보원장'!$F$5:$F$68,$C10,'5.담보원장'!$B$5:$B$68,E$4)) -> 0 | F10: =IF($C10="","",SUMIFS('5.담보원장'!$G$5:$G$68,'5.담보원장'!$F$5:$F$68,$C10,'5.담보원장'!$B$5:$B$68,F$4)) -> 0 | G10: =IF($C10="","",SUMIFS('5.담보원장'!$G$5:$G$68,'5.담보원장'!$F$5:$F$68,$C10,'5.담보원장'!$B$5:$B$68,G$4)) -> 0 | H10: =IF($C10="","",SUM(E10:G10)) -> 0 | I10: =IF('4.담보마스터'!F9="","",'4.담보마스터'!F9) -> 50 | J10: =IF(OR($C10="",$I10=""),"",$H10-$I10) -> -50 | K10: =IF($C10="","",IF($I10="","－",IF($H10=0,"미가입",IF($H10>=$I10,"충분","부족")))) -> 미가입 | L10: =IF('4.담보마스터'!G9="","",'4.담보마스터'!G9) -> 1000 | M10: =IF(OR($C10="",$L10=""),"",$H10-$L10) -> -1000 | N10: =IF('4.담보마스터'!H9="","",'4.담보마스터'!H9) -> ★★★2026 3대 핵심 트렌드 ③. 5세대 실손(2026.5.6~)의 비중증 비급여 축소로 정액 수술비의 역할이 커졌습니다. 비중증 비급여 자기부담 30% → 50%, 연간 한도 5,000만 → 1,000만, 통원 1회 20만·병의원 입원 1회 300만 제한 신설. 정액 수술비는 급여·비급여를 따지지 않고 수술확인서만으로 정액 지급되며 반복 청구가 가능해 이 공백을 메웁니다. 1~5종 종수술비(5종 기준 500~1,000만원)가 표준이며, DB손보 '반값 종수술비' 등 판매 경쟁 진행 중 | O10: =IF('4.담보마스터'!I9="","",'4.담보마스터'!I9) -> ★미가입 — 최우선 검토 대상. 계약①은 '16대질병수술 100만원' 한정형만 있어, 16대에 들어가지 않는 수술은 정액 보험금이 0원입니다. 예: 비중증 수술비 300만원 발생 시 5세대 실손 기준 본인부담이 90만원 → 150만원으로 늘어나는데, 신OO님은 2세대 실손이라 실손 쪽 방어는 유리하나 '실손이 아예 안 되는 항목·초과분'은 정액 수술비로만 메울 수 있습니다
B11: =IF('4.담보마스터'!C10="","",'4.담보마스터'!C10) -> 수술·입원 | C11: =IF('4.담보마스터'!D10="","",'4.담보마스터'!D10) -> 수술비-N대질병 | D11: =IF('4.담보마스터'!E10="","",'4.담보마스터'!E10) -> 만원 | E11: =IF($C11="","",SUMIFS('5.담보원장'!$G$5:$G$68,'5.담보원장'!$F$5:$F$68,$C11,'5.담보원장'!$B$5:$B$68,E$4)) -> 100 | F11: =IF($C11="","",SUMIFS('5.담보원장'!$G$5:$G$68,'5.담보원장'!$F$5:$F$68,$C11,'5.담보원장'!$B$5:$B$68,F$4)) -> 0 | G11: =IF($C11="","",SUMIFS('5.담보원장'!$G$5:$G$68,'5.담보원장'!$F$5:$F$68,$C11,'5.담보원장'!$B$5:$B$68,G$4)) -> 0 | H11: =IF($C11="","",SUM(E11:G11)) -> 100 | I11: =IF('4.담보마스터'!F10="","",'4.담보마스터'!F10) -> 100 | J11: =IF(OR($C11="",$I11=""),"",$H11-$I11) -> 0 | K11: =IF($C11="","",IF($I11="","－",IF($H11=0,"미가입",IF($H11>=$I11,"충분","부족")))) -> 충분 | L11: =IF('4.담보마스터'!G10="","",'4.담보마스터'!G10) -> 500 | M11: =IF(OR($C11="",$L11=""),"",$H11-$L11) -> -400 | N11: =IF('4.담보마스터'!H10="","",'4.담보마스터'!H10) -> N대 범위 확대(16대 → 38대·61대·105대). 다만 최근에는 질병군을 한정하지 않는 1~5종 종수술비 + 질병통합치료비 조합으로 무게중심이 이동 | O11: =IF('4.담보마스터'!I10="","",'4.담보마스터'!I10) -> 계약① 16대질병수술 100만원. 2010년 약관 기준이라 질병군 범위가 좁고, '16대에 해당하는지'를 매번 따져야 하는 한정형 구조입니다
B12: =IF('4.담보마스터'!C11="","",'4.담보마스터'!C11) -> 수술·입원 | C12: =IF('4.담보마스터'!D11="","",'4.담보마스터'!D11) -> 수술비-재해(상해) | D12: =IF('4.담보마스터'!E11="","",'4.담보마스터'!E11) -> 만원 | E12: =IF($C12="","",SUMIFS('5.담보원장'!$G$5:$G$68,'5.담보원장'!$F$5:$F$68,$C12,'5.담보원장'!$B$5:$B$68,E$4)) -> 0 | F12: =IF($C12="","",SUMIFS('5.담보원장'!$G$5:$G$68,'5.담보원장'!$F$5:$F$68,$C12,'5.담보원장'!$B$5:$B$68,F$4)) -> 0 | G12: =IF($C12="","",SUMIFS('5.담보원장'!$G$5:$G$68,'5.담보원장'!$F$5:$F$68,$C12,'5.담보원장'!$B$5:$B$68,G$4)) -> 0 | H12: =IF($C12="","",SUM(E12:G12)) -> 0 | I12: =IF('4.담보마스터'!F11="","",'4.담보마스터'!F11) -> 100 | J12: =IF(OR($C12="",$I12=""),"",$H12-$I12) -> -100 | K12: =IF($C12="","",IF($I12="","－",IF($H12=0,"미가입",IF($H12>=$I12,"충분","부족")))) -> 미가입 | L12: =IF('4.담보마스터'!G11="","",'4.담보마스터'!G11) -> 1000 | M12: =IF(OR($C12="",$L12=""),"",$H12-$L12) -> -1000 | N12: =IF('4.담보마스터'!H11="","",'4.담보마스터'!H11) -> 상해 1~5종 종수술비 + 부위별 특정상해수술 병행 설계가 표준. 정액형이라 급여·비급여 구분 없이 지급되며, 5세대 실손 축소의 대안 담보로 함께 거론됨 | O12: =IF('4.담보마스터'!I11="","",'4.담보마스터'!I11) -> 미가입. 계약②는 관절·인대·척추 등 부위별 특정상해수술만 보유해 해당 부위가 아닌 상해수술은 정액 보험금이 0원입니다
B13: =IF('4.담보마스터'!C12="","",'4.담보마스터'!C12) -> 수술·입원 | C13: =IF('4.담보마스터'!D12="","",'4.담보마스터'!D12) -> 질병통합치료비(검사·시술·수술 포괄) | D13: =IF('4.담보마스터'!E12="","",'4.담보마스터'!E12) -> 만원 | E13: =IF($C13="","",SUMIFS('5.담보원장'!$G$5:$G$68,'5.담보원장'!$F$5:$F$68,$C13,'5.담보원장'!$B$5:$B$68,E$4)) -> 0 | F13: =IF($C13="","",SUMIFS('5.담보원장'!$G$5:$G$68,'5.담보원장'!$F$5:$F$68,$C13,'5.담보원장'!$B$5:$B$68,F$4)) -> 0 | G13: =IF($C13="","",SUMIFS('5.담보원장'!$G$5:$G$68,'5.담보원장'!$F$5:$F$68,$C13,'5.담보원장'!$B$5:$B$68,G$4)) -> 0 | H13: =IF($C13="","",SUM(E13:G13)) -> 0 | I13: =IF('4.담보마스터'!F12="","",'4.담보마스터'!F12) | J13: =IF(OR($C13="",$I13=""),"",$H13-$I13) | K13: =IF($C13="","",IF($I13="","－",IF($H13=0,"미가입",IF($H13>=$I13,"충분","부족")))) -> － | L13: =IF('4.담보마스터'!G12="","",'4.담보마스터'!G12) -> 1000 | M13: =IF(OR($C13="",$L13=""),"",$H13-$L13) -> -1000 | N13: =IF('4.담보마스터'!H12="","",'4.담보마스터'!H12) -> ★2026 신설 트렌드 담보. 검사 → 시술 → 수술 → 중증치료를 하나로 묶어 정액 지급하는 확장형 담보. 5세대 실손의 통원·외래 부담 증가에 대응하는 대안으로 수술비와 함께 급부상. 메리츠·KB손보·하나손보 등 판매 | O13: =IF('4.담보마스터'!I12="","",'4.담보마스터'!I12) -> 미가입. 수술 단계만 보는 수술비보다 앞단(검사·시술)까지 포괄해 실손 축소분을 넓게 메우는 구조
B14: =IF('4.담보마스터'!C13="","",'4.담보마스터'!C13) -> 수술·입원 | C14: =IF('4.담보마스터'!D13="","",'4.담보마스터'!D13) -> 입원일당-질병 | D14: =IF('4.담보마스터'!E13="","",'4.담보마스터'!E13) -> 만원/일 | E14: =IF($C14="","",SUMIFS('5.담보원장'!$G$5:$G$68,'5.담보원장'!$F$5:$F$68,$C14,'5.담보원장'!$B$5:$B$68,E$4)) -> 2 | F14: =IF($C14="","",SUMIFS('5.담보원장'!$G$5:$G$68,'5.담보원장'!$F$5:$F$68,$C14,'5.담보원장'!$B$5:$B$68,F$4)) -> 0 | G14: =IF($C14="","",SUMIFS('5.담보원장'!$G$5:$G$68,'5.담보원장'!$F$5:$F$68,$C14,'5.담보원장'!$B$5:$B$68,G$4)) -> 0 | H14: =IF($C14="","",SUM(E14:G14)) -> 2 | I14: =IF('4.담보마스터'!F13="","",'4.담보마스터'!F13) -> 3 | J14: =IF(OR($C14="",$I14=""),"",$H14-$I14) -> -1 | K14: =IF($C14="","",IF($I14="","－",IF($H14=0,"미가입",IF($H14>=$I14,"충분","부족")))) -> 부족 | L14: =IF('4.담보마스터'!G13="","",'4.담보마스터'!G13) -> 5 | M14: =IF(OR($C14="",$L14=""),"",$H14-$L14) -> -3 | N14: =IF('4.담보마스터'!H13="","",'4.담보마스터'!H13) -> 상급종합병원 가산형·중환자실 가산형 확산. 기본 3만 + 상급종합 추가 3만 구조 | O14: =IF('4.담보마스터'!I13="","",'4.담보마스터'!I13) -> 계약① 2만 (권장 3만 대비 -1만)
B15: =IF('4.담보마스터'!C14="","",'4.담보마스터'!C14) -> 수술·입원 | C15: =IF('4.담보마스터'!D14="","",'4.담보마스터'!D14) -> 입원일당-N대질병 | D15: =IF('4.담보마스터'!E14="","",'4.담보마스터'!E14) -> 만원/일 | E15: =IF($C15="","",SUMIFS('5.담보원장'!$G$5:$G$68,'5.담보원장'!$F$5:$F$68,$C15,'5.담보원장'!$B$5:$B$68,E$4)) -> 2 | F15: =IF($C15="","",SUMIFS('5.담보원장'!$G$5:$G$68,'5.담보원장'!$F$5:$F$68,$C15,'5.담보원장'!$B$5:$B$68,F$4)) -> 0 | G15: =IF($C15="","",SUMIFS('5.담보원장'!$G$5:$G$68,'5.담보원장'!$F$5:$F$68,$C15,'5.담보원장'!$B$5:$B$68,G$4)) -> 0 | H15: =IF($C15="","",SUM(E15:G15)) -> 2 | I15: =IF('4.담보마스터'!F14="","",'4.담보마스터'!F14) -> 3 | J15: =IF(OR($C15="",$I15=""),"",$H15-$I15) -> -1 | K15: =IF($C15="","",IF($I15="","－",IF($H15=0,"미가입",IF($H15>=$I15,"충분","부족")))) -> 부족 | L15: =IF('4.담보마스터'!G14="","",'4.담보마스터'!G14) | M15: =IF(OR($C15="",$L15=""),"",$H15-$L15) | N15: =IF('4.담보마스터'!H14="","",'4.담보마스터'!H14) -> 4대성인병 → 15대·31대 성인질환으로 대상 확대 | O15: =IF('4.담보마스터'!I14="","",'4.담보마스터'!I14) -> 계약① 4대성인병 1만 + 5대만성질병 1만 = 2만
B16: =IF('4.담보마스터'!C15="","",'4.담보마스터'!C15) -> 수술·입원 | C16: =IF('4.담보마스터'!D15="","",'4.담보마스터'!D15) -> 입원일당-재해(상해) | D16: =IF('4.담보마스터'!E15="","",'4.담보마스터'!E15) -> 만원/일 | E16: =IF($C16="","",SUMIFS('5.담보원장'!$G$5:$G$68,'5.담보원장'!$F$5:$F$68,$C16,'5.담보원장'!$B$5:$B$68,E$4)) -> 2 | F16: =IF($C16="","",SUMIFS('5.담보원장'!$G$5:$G$68,'5.담보원장'!$F$5:$F$68,$C16,'5.담보원장'!$B$5:$B$68,F$4)) -> 0 | G16: =IF($C16="","",SUMIFS('5.담보원장'!$G$5:$G$68,'5.담보원장'!$F$5:$F$68,$C16,'5.담보원장'!$B$5:$B$68,G$4)) -> 0 | H16: =IF($C16="","",SUM(E16:G16)) -> 2 | I16: =IF('4.담보마스터'!F15="","",'4.담보마스터'!F15) -> 3 | J16: =IF(OR($C16="",$I16=""),"",$H16-$I16) -> -1 | K16: =IF($C16="","",IF($I16="","－",IF($H16=0,"미가입",IF($H16>=$I16,"충분","부족")))) -> 부족 | L16: =IF('4.담보마스터'!G15="","",'4.담보마스터'!G15) -> 5 | M16: =IF(OR($C16="",$L16=""),"",$H16-$L16) -> -3 | N16: =IF('4.담보마스터'!H15="","",'4.담보마스터'!H15) -> 상해입원일당은 1일차부터 지급이 표준화 | O16: =IF('4.담보마스터'!I15="","",'4.담보마스터'!I15) -> 계약① 2만 (권장 3만 대비 -1만). 계약② 교통상해입원일당 1만 별도
B17: =IF('4.담보마스터'!C16="","",'4.담보마스터'!C16) -> 수술·입원 | C17: =IF('4.담보마스터'!D16="","",'4.담보마스터'!D16) -> 통원일당 | D17: =IF('4.담보마스터'!E16="","",'4.담보마스터'!E16) -> 만원/일 | E17: =IF($C17="","",SUMIFS('5.담보원장'!$G$5:$G$68,'5.담보원장'!$F$5:$F$68,$C17,'5.담보원장'!$B$5:$B$68,E$4)) -> 0 | F17: =IF($C17="","",SUMIFS('5.담보원장'!$G$5:$G$68,'5.담보원장'!$F$5:$F$68,$C17,'5.담보원장'!$B$5:$B$68,F$4)) -> 0 | G17: =IF($C17="","",SUMIFS('5.담보원장'!$G$5:$G$68,'5.담보원장'!$F$5:$F$68,$C17,'5.담보원장'!$B$5:$B$68,G$4)) -> 0 | H17: =IF($C17="","",SUM(E17:G17)) -> 0 | I17: =IF('4.담보마스터'!F16="","",'4.담보마스터'!F16) | J17: =IF(OR($C17="",$I17=""),"",$H17-$I17) | K17: =IF($C17="","",IF($I17="","－",IF($H17=0,"미가입",IF($H17>=$I17,"충분","부족")))) -> － | L17: =IF('4.담보마스터'!G16="","",'4.담보마스터'!G16) | M17: =IF(OR($C17="",$L17=""),"",$H17-$L17) | N17: =IF('4.담보마스터'!H16="","",'4.담보마스터'!H16) -> 실손과 중복되어 최근 축소 추세 | O17: =IF('4.담보마스터'!I16="","",'4.담보마스터'!I16) -> 미가입
... B81: =IF('4.담보마스터'!C80="","",'4.담보마스터'!C80) -> (추가) | C81: =IF('4.담보마스터'!D80="","",'4.담보마스터'!D80) -> 여기부터 담보를 추가하세요 | D81: =IF('4.담보마스터'!E80="","",'4.담보마스터'!E80) -> 만원 | E81: =IF($C81="","",SUMIFS('5.담보원장'!$G$5:$G$68,'5.담보원장'!$F$5:$F$68,$C81,'5.담보원장'!$B$5:$B$68,E$4)) -> 0 | F81: =IF($C81="","",SUMIFS('5.담보원장'!$G$5:$G$68,'5.담보원장'!$F$5:$F$68,$C81,'5.담보원장'!$B$5:$B$68,F$4)) -> 0 | G81: =IF($C81="","",SUMIFS('5.담보원장'!$G$5:$G$68,'5.담보원장'!$F$5:$F$68,$C81,'5.담보원장'!$B$5:$B$68,G$4)) -> 0 | H81: =IF($C81="","",SUM(E81:G81)) -> 0 | I81: =IF('4.담보마스터'!F80="","",'4.담보마스터'!F80) | J81: =IF(OR($C81="",$I81=""),"",$H81-$I81) | K81: =IF($C81="","",IF($I81="","－",IF($H81=0,"미가입",IF($H81>=$I81,"충분","부족")))) -> － | L81: =IF('4.담보마스터'!G80="","",'4.담보마스터'!G80) | M81: =IF(OR($C81="",$L81=""),"",$H81-$L81) | N81: =IF('4.담보마스터'!H80="","",'4.담보마스터'!H80) | O81: =IF('4.담보마스터'!I80="","",'4.담보마스터'!I80)
B82: =IF('4.담보마스터'!#REF!="","",'4.담보마스터'!#REF!) -> #REF! | C82: =IF('4.담보마스터'!#REF!="","",'4.담보마스터'!#REF!) -> #REF! | D82: =IF('4.담보마스터'!#REF!="","",'4.담보마스터'!#REF!) -> #REF! | E82: =IF($C82="","",SUMIFS('5.담보원장'!$G$5:$G$68,'5.담보원장'!$F$5:$F$68,$C82,'5.담보원장'!$B$5:$B$68,E$4)) -> #REF! | F82: =IF($C82="","",SUMIFS('5.담보원장'!$G$5:$G$68,'5.담보원장'!$F$5:$F$68,$C82,'5.담보원장'!$B$5:$B$68,F$4)) -> #REF! | G82: =IF($C82="","",SUMIFS('5.담보원장'!$G$5:$G$68,'5.담보원장'!$F$5:$F$68,$C82,'5.담보원장'!$B$5:$B$68,G$4)) -> #REF! | H82: =IF($C82="","",SUM(E82:G82)) -> #REF! | I82: =IF('4.담보마스터'!#REF!="","",'4.담보마스터'!#REF!) -> #REF! | J82: =IF(OR($C82="",$I82=""),"",$H82-$I82) -> #REF! | K82: =IF($C82="","",IF($I82="","－",IF($H82=0,"미가입",IF($H82>=$I82,"충분","부족")))) -> #REF! | L82: =IF('4.담보마스터'!#REF!="","",'4.담보마스터'!#REF!) -> #REF! | M82: =IF(OR($C82="",$L82=""),"",$H82-$L82) -> #REF! | N82: =IF('4.담보마스터'!#REF!="","",'4.담보마스터'!#REF!) -> #REF! | O82: =IF('4.담보마스터'!#REF!="","",'4.담보마스터'!#REF!) -> #REF!
B83: =IF('4.담보마스터'!#REF!="","",'4.담보마스터'!#REF!) -> #REF! | C83: =IF('4.담보마스터'!#REF!="","",'4.담보마스터'!#REF!) -> #REF! | D83: =IF('4.담보마스터'!#REF!="","",'4.담보마스터'!#REF!) -> #REF! | E83: =IF($C83="","",SUMIFS('5.담보원장'!$G$5:$G$68,'5.담보원장'!$F$5:$F$68,$C83,'5.담보원장'!$B$5:$B$68,E$4)) -> #REF! | F83: =IF($C83="","",SUMIFS('5.담보원장'!$G$5:$G$68,'5.담보원장'!$F$5:$F$68,$C83,'5.담보원장'!$B$5:$B$68,F$4)) -> #REF! | G83: =IF($C83="","",SUMIFS('5.담보원장'!$G$5:$G$68,'5.담보원장'!$F$5:$F$68,$C83,'5.담보원장'!$B$5:$B$68,G$4)) -> #REF! | H83: =IF($C83="","",SUM(E83:G83)) -> #REF! | I83: =IF('4.담보마스터'!#REF!="","",'4.담보마스터'!#REF!) -> #REF! | J83: =IF(OR($C83="",$I83=""),"",$H83-$I83) -> #REF! | K83: =IF($C83="","",IF($I83="","－",IF($H83=0,"미가입",IF($H83>=$I83,"충분","부족")))) -> #REF! | L83: =IF('4.담보마스터'!#REF!="","",'4.담보마스터'!#REF!) -> #REF! | M83: =IF(OR($C83="",$L83=""),"",$H83-$L83) -> #REF! | N83: =IF('4.담보마스터'!#REF!="","",'4.담보마스터'!#REF!) -> #REF! | O83: =IF('4.담보마스터'!#REF!="","",'4.담보마스터'!#REF!) -> #REF!
B84: =IF('4.담보마스터'!#REF!="","",'4.담보마스터'!#REF!) -> #REF! | C84: =IF('4.담보마스터'!#REF!="","",'4.담보마스터'!#REF!) -> #REF! | D84: =IF('4.담보마스터'!#REF!="","",'4.담보마스터'!#REF!) -> #REF! | E84: =IF($C84="","",SUMIFS('5.담보원장'!$G$5:$G$68,'5.담보원장'!$F$5:$F$68,$C84,'5.담보원장'!$B$5:$B$68,E$4)) -> #REF! | F84: =IF($C84="","",SUMIFS('5.담보원장'!$G$5:$G$68,'5.담보원장'!$F$5:$F$68,$C84,'5.담보원장'!$B$5:$B$68,F$4)) -> #REF! | G84: =IF($C84="","",SUMIFS('5.담보원장'!$G$5:$G$68,'5.담보원장'!$F$5:$F$68,$C84,'5.담보원장'!$B$5:$B$68,G$4)) -> #REF! | H84: =IF($C84="","",SUM(E84:G84)) -> #REF! | I84: =IF('4.담보마스터'!#REF!="","",'4.담보마스터'!#REF!) -> #REF! | J84: =IF(OR($C84="",$I84=""),"",$H84-$I84) -> #REF! | K84: =IF($C84="","",IF($I84="","－",IF($H84=0,"미가입",IF($H84>=$I84,"충분","부족")))) -> #REF! | L84: =IF('4.담보마스터'!#REF!="","",'4.담보마스터'!#REF!) -> #REF! | M84: =IF(OR($C84="",$L84=""),"",$H84-$L84) -> #REF! | N84: =IF('4.담보마스터'!#REF!="","",'4.담보마스터'!#REF!) -> #REF! | O84: =IF('4.담보마스터'!#REF!="","",'4.담보마스터'!#REF!) -> #REF!
B85: =IF('4.담보마스터'!#REF!="","",'4.담보마스터'!#REF!) -> #REF! | C85: =IF('4.담보마스터'!#REF!="","",'4.담보마스터'!#REF!) -> #REF! | D85: =IF('4.담보마스터'!#REF!="","",'4.담보마스터'!#REF!) -> #REF! | E85: =IF($C85="","",SUMIFS('5.담보원장'!$G$5:$G$68,'5.담보원장'!$F$5:$F$68,$C85,'5.담보원장'!$B$5:$B$68,E$4)) -> #REF! | F85: =IF($C85="","",SUMIFS('5.담보원장'!$G$5:$G$68,'5.담보원장'!$F$5:$F$68,$C85,'5.담보원장'!$B$5:$B$68,F$4)) -> #REF! | G85: =IF($C85="","",SUMIFS('5.담보원장'!$G$5:$G$68,'5.담보원장'!$F$5:$F$68,$C85,'5.담보원장'!$B$5:$B$68,G$4)) -> #REF! | H85: =IF($C85="","",SUM(E85:G85)) -> #REF! | I85: =IF('4.담보마스터'!#REF!="","",'4.담보마스터'!#REF!) -> #REF! | J85: =IF(OR($C85="",$I85=""),"",$H85-$I85) -> #REF! | K85: =IF($C85="","",IF($I85="","－",IF($H85=0,"미가입",IF($H85>=$I85,"충분","부족")))) -> #REF! | L85: =IF('4.담보마스터'!#REF!="","",'4.담보마스터'!#REF!) -> #REF! | M85: =IF(OR($C85="",$L85=""),"",$H85-$L85) -> #REF! | N85: =IF('4.담보마스터'!#REF!="","",'4.담보마스터'!#REF!) -> #REF! | O85: =IF('4.담보마스터'!#REF!="","",'4.담보마스터'!#REF!) -> #REF!
B86: =IF('4.담보마스터'!#REF!="","",'4.담보마스터'!#REF!) -> #REF! | C86: =IF('4.담보마스터'!#REF!="","",'4.담보마스터'!#REF!) -> #REF! | D86: =IF('4.담보마스터'!#REF!="","",'4.담보마스터'!#REF!) -> #REF! | E86: =IF($C86="","",SUMIFS('5.담보원장'!$G$5:$G$68,'5.담보원장'!$F$5:$F$68,$C86,'5.담보원장'!$B$5:$B$68,E$4)) -> #REF! | F86: =IF($C86="","",SUMIFS('5.담보원장'!$G$5:$G$68,'5.담보원장'!$F$5:$F$68,$C86,'5.담보원장'!$B$5:$B$68,F$4)) -> #REF! | G86: =IF($C86="","",SUMIFS('5.담보원장'!$G$5:$G$68,'5.담보원장'!$F$5:$F$68,$C86,'5.담보원장'!$B$5:$B$68,G$4)) -> #REF! | H86: =IF($C86="","",SUM(E86:G86)) -> #REF! | I86: =IF('4.담보마스터'!#REF!="","",'4.담보마스터'!#REF!) -> #REF! | J86: =IF(OR($C86="",$I86=""),"",$H86-$I86) -> #REF! | K86: =IF($C86="","",IF($I86="","－",IF($H86=0,"미가입",IF($H86>=$I86,"충분","부족")))) -> #REF! | L86: =IF('4.담보마스터'!#REF!="","",'4.담보마스터'!#REF!) -> #REF! | M86: =IF(OR($C86="",$L86=""),"",$H86-$L86) -> #REF! | N86: =IF('4.담보마스터'!#REF!="","",'4.담보마스터'!#REF!) -> #REF! | O86: =IF('4.담보마스터'!#REF!="","",'4.담보마스터'!#REF!) -> #REF!
B87: =IF('4.담보마스터'!#REF!="","",'4.담보마스터'!#REF!) -> #REF! | C87: =IF('4.담보마스터'!#REF!="","",'4.담보마스터'!#REF!) -> #REF! | D87: =IF('4.담보마스터'!#REF!="","",'4.담보마스터'!#REF!) -> #REF! | E87: =IF($C87="","",SUMIFS('5.담보원장'!$G$5:$G$68,'5.담보원장'!$F$5:$F$68,$C87,'5.담보원장'!$B$5:$B$68,E$4)) -> #REF! | F87: =IF($C87="","",SUMIFS('5.담보원장'!$G$5:$G$68,'5.담보원장'!$F$5:$F$68,$C87,'5.담보원장'!$B$5:$B$68,F$4)) -> #REF! | G87: =IF($C87="","",SUMIFS('5.담보원장'!$G$5:$G$68,'5.담보원장'!$F$5:$F$68,$C87,'5.담보원장'!$B$5:$B$68,G$4)) -> #REF! | H87: =IF($C87="","",SUM(E87:G87)) -> #REF! | I87: =IF('4.담보마스터'!#REF!="","",'4.담보마스터'!#REF!) -> #REF! | J87: =IF(OR($C87="",$I87=""),"",$H87-$I87) -> #REF! | K87: =IF($C87="","",IF($I87="","－",IF($H87=0,"미가입",IF($H87>=$I87,"충분","부족")))) -> #REF! | L87: =IF('4.담보마스터'!#REF!="","",'4.담보마스터'!#REF!) -> #REF! | M87: =IF(OR($C87="",$L87=""),"",$H87-$L87) -> #REF! | N87: =IF('4.담보마스터'!#REF!="","",'4.담보마스터'!#REF!) -> #REF! | O87: =IF('4.담보마스터'!#REF!="","",'4.담보마스터'!#REF!) -> #REF!
B88: =IF('4.담보마스터'!#REF!="","",'4.담보마스터'!#REF!) -> #REF! | C88: =IF('4.담보마스터'!#REF!="","",'4.담보마스터'!#REF!) -> #REF! | D88: =IF('4.담보마스터'!#REF!="","",'4.담보마스터'!#REF!) -> #REF! | E88: =IF($C88="","",SUMIFS('5.담보원장'!$G$5:$G$68,'5.담보원장'!$F$5:$F$68,$C88,'5.담보원장'!$B$5:$B$68,E$4)) -> #REF! | F88: =IF($C88="","",SUMIFS('5.담보원장'!$G$5:$G$68,'5.담보원장'!$F$5:$F$68,$C88,'5.담보원장'!$B$5:$B$68,F$4)) -> #REF! | G88: =IF($C88="","",SUMIFS('5.담보원장'!$G$5:$G$68,'5.담보원장'!$F$5:$F$68,$C88,'5.담보원장'!$B$5:$B$68,G$4)) -> #REF! | H88: =IF($C88="","",SUM(E88:G88)) -> #REF! | I88: =IF('4.담보마스터'!#REF!="","",'4.담보마스터'!#REF!) -> #REF! | J88: =IF(OR($C88="",$I88=""),"",$H88-$I88) -> #REF! | K88: =IF($C88="","",IF($I88="","－",IF($H88=0,"미가입",IF($H88>=$I88,"충분","부족")))) -> #REF! | L88: =IF('4.담보마스터'!#REF!="","",'4.담보마스터'!#REF!) -> #REF! | M88: =IF(OR($C88="",$L88=""),"",$H88-$L88) -> #REF! | N88: =IF('4.담보마스터'!#REF!="","",'4.담보마스터'!#REF!) -> #REF! | O88: =IF('4.담보마스터'!#REF!="","",'4.담보마스터'!#REF!) -> #REF!
B89: =IF('4.담보마스터'!#REF!="","",'4.담보마스터'!#REF!) -> #REF! | C89: =IF('4.담보마스터'!#REF!="","",'4.담보마스터'!#REF!) -> #REF! | D89: =IF('4.담보마스터'!#REF!="","",'4.담보마스터'!#REF!) -> #REF! | E89: =IF($C89="","",SUMIFS('5.담보원장'!$G$5:$G$68,'5.담보원장'!$F$5:$F$68,$C89,'5.담보원장'!$B$5:$B$68,E$4)) -> #REF! | F89: =IF($C89="","",SUMIFS('5.담보원장'!$G$5:$G$68,'5.담보원장'!$F$5:$F$68,$C89,'5.담보원장'!$B$5:$B$68,F$4)) -> #REF! | G89: =IF($C89="","",SUMIFS('5.담보원장'!$G$5:$G$68,'5.담보원장'!$F$5:$F$68,$C89,'5.담보원장'!$B$5:$B$68,G$4)) -> #REF! | H89: =IF($C89="","",SUM(E89:G89)) -> #REF! | I89: =IF('4.담보마스터'!#REF!="","",'4.담보마스터'!#REF!) -> #REF! | J89: =IF(OR($C89="",$I89=""),"",$H89-$I89) -> #REF! | K89: =IF($C89="","",IF($I89="","－",IF($H89=0,"미가입",IF($H89>=$I89,"충분","부족")))) -> #REF! | L89: =IF('4.담보마스터'!#REF!="","",'4.담보마스터'!#REF!) -> #REF! | M89: =IF(OR($C89="",$L89=""),"",$H89-$L89) -> #REF! | N89: =IF('4.담보마스터'!#REF!="","",'4.담보마스터'!#REF!) -> #REF! | O89: =IF('4.담보마스터'!#REF!="","",'4.담보마스터'!#REF!) -> #REF!
B90: =IF('4.담보마스터'!#REF!="","",'4.담보마스터'!#REF!) -> #REF! | C90: =IF('4.담보마스터'!#REF!="","",'4.담보마스터'!#REF!) -> #REF! | D90: =IF('4.담보마스터'!#REF!="","",'4.담보마스터'!#REF!) -> #REF! | E90: =IF($C90="","",SUMIFS('5.담보원장'!$G$5:$G$68,'5.담보원장'!$F$5:$F$68,$C90,'5.담보원장'!$B$5:$B$68,E$4)) -> #REF! | F90: =IF($C90="","",SUMIFS('5.담보원장'!$G$5:$G$68,'5.담보원장'!$F$5:$F$68,$C90,'5.담보원장'!$B$5:$B$68,F$4)) -> #REF! | G90: =IF($C90="","",SUMIFS('5.담보원장'!$G$5:$G$68,'5.담보원장'!$F$5:$F$68,$C90,'5.담보원장'!$B$5:$B$68,G$4)) -> #REF! | H90: =IF($C90="","",SUM(E90:G90)) -> #REF! | I90: =IF('4.담보마스터'!#REF!="","",'4.담보마스터'!#REF!) -> #REF! | J90: =IF(OR($C90="",$I90=""),"",$H90-$I90) -> #REF! | K90: =IF($C90="","",IF($I90="","－",IF($H90=0,"미가입",IF($H90>=$I90,"충분","부족")))) -> #REF! | L90: =IF('4.담보마스터'!#REF!="","",'4.담보마스터'!#REF!) -> #REF! | M90: =IF(OR($C90="",$L90=""),"",$H90-$L90) -> #REF! | N90: =IF('4.담보마스터'!#REF!="","",'4.담보마스터'!#REF!) -> #REF! | O90: =IF('4.담보마스터'!#REF!="","",'4.담보마스터'!#REF!) -> #REF!
B91: =IF('4.담보마스터'!#REF!="","",'4.담보마스터'!#REF!) -> #REF! | C91: =IF('4.담보마스터'!#REF!="","",'4.담보마스터'!#REF!) -> #REF! | D91: =IF('4.담보마스터'!#REF!="","",'4.담보마스터'!#REF!) -> #REF! | E91: =IF($C91="","",SUMIFS('5.담보원장'!$G$5:$G$68,'5.담보원장'!$F$5:$F$68,$C91,'5.담보원장'!$B$5:$B$68,E$4)) -> #REF! | F91: =IF($C91="","",SUMIFS('5.담보원장'!$G$5:$G$68,'5.담보원장'!$F$5:$F$68,$C91,'5.담보원장'!$B$5:$B$68,F$4)) -> #REF! | G91: =IF($C91="","",SUMIFS('5.담보원장'!$G$5:$G$68,'5.담보원장'!$F$5:$F$68,$C91,'5.담보원장'!$B$5:$B$68,G$4)) -> #REF! | H91: =IF($C91="","",SUM(E91:G91)) -> #REF! | I91: =IF('4.담보마스터'!#REF!="","",'4.담보마스터'!#REF!) -> #REF! | J91: =IF(OR($C91="",$I91=""),"",$H91-$I91) -> #REF! | K91: =IF($C91="","",IF($I91="","－",IF($H91=0,"미가입",IF($H91>=$I91,"충분","부족")))) -> #REF! | L91: =IF('4.담보마스터'!#REF!="","",'4.담보마스터'!#REF!) -> #REF! | M91: =IF(OR($C91="",$L91=""),"",$H91-$L91) -> #REF! | N91: =IF('4.담보마스터'!#REF!="","",'4.담보마스터'!#REF!) -> #REF! | O91: =IF('4.담보마스터'!#REF!="","",'4.담보마스터'!#REF!) -> #REF!
B92: =IF('4.담보마스터'!#REF!="","",'4.담보마스터'!#REF!) -> #REF! | C92: =IF('4.담보마스터'!#REF!="","",'4.담보마스터'!#REF!) -> #REF! | D92: =IF('4.담보마스터'!#REF!="","",'4.담보마스터'!#REF!) -> #REF! | E92: =IF($C92="","",SUMIFS('5.담보원장'!$G$5:$G$68,'5.담보원장'!$F$5:$F$68,$C92,'5.담보원장'!$B$5:$B$68,E$4)) -> #REF! | F92: =IF($C92="","",SUMIFS('5.담보원장'!$G$5:$G$68,'5.담보원장'!$F$5:$F$68,$C92,'5.담보원장'!$B$5:$B$68,F$4)) -> #REF! | G92: =IF($C92="","",SUMIFS('5.담보원장'!$G$5:$G$68,'5.담보원장'!$F$5:$F$68,$C92,'5.담보원장'!$B$5:$B$68,G$4)) -> #REF! | H92: =IF($C92="","",SUM(E92:G92)) -> #REF! | I92: =IF('4.담보마스터'!#REF!="","",'4.담보마스터'!#REF!) -> #REF! | J92: =IF(OR($C92="",$I92=""),"",$H92-$I92) -> #REF! | K92: =IF($C92="","",IF($I92="","－",IF($H92=0,"미가입",IF($H92>=$I92,"충분","부족")))) -> #REF! | L92: =IF('4.담보마스터'!#REF!="","",'4.담보마스터'!#REF!) -> #REF! | M92: =IF(OR($C92="",$L92=""),"",$H92-$L92) -> #REF! | N92: =IF('4.담보마스터'!#REF!="","",'4.담보마스터'!#REF!) -> #REF! | O92: =IF('4.담보마스터'!#REF!="","",'4.담보마스터'!#REF!) -> #REF!
B93: =IF('4.담보마스터'!#REF!="","",'4.담보마스터'!#REF!) -> #REF! | C93: =IF('4.담보마스터'!#REF!="","",'4.담보마스터'!#REF!) -> #REF! | D93: =IF('4.담보마스터'!#REF!="","",'4.담보마스터'!#REF!) -> #REF! | E93: =IF($C93="","",SUMIFS('5.담보원장'!$G$5:$G$68,'5.담보원장'!$F$5:$F$68,$C93,'5.담보원장'!$B$5:$B$68,E$4)) -> #REF! | F93: =IF($C93="","",SUMIFS('5.담보원장'!$G$5:$G$68,'5.담보원장'!$F$5:$F$68,$C93,'5.담보원장'!$B$5:$B$68,F$4)) -> #REF! | G93: =IF($C93="","",SUMIFS('5.담보원장'!$G$5:$G$68,'5.담보원장'!$F$5:$F$68,$C93,'5.담보원장'!$B$5:$B$68,G$4)) -> #REF! | H93: =IF($C93="","",SUM(E93:G93)) -> #REF! | I93: =IF('4.담보마스터'!#REF!="","",'4.담보마스터'!#REF!) -> #REF! | J93: =IF(OR($C93="",$I93=""),"",$H93-$I93) -> #REF! | K93: =IF($C93="","",IF($I93="","－",IF($H93=0,"미가입",IF($H93>=$I93,"충분","부족")))) -> #REF! | L93: =IF('4.담보마스터'!#REF!="","",'4.담보마스터'!#REF!) -> #REF! | M93: =IF(OR($C93="",$L93=""),"",$H93-$L93) -> #REF! | N93: =IF('4.담보마스터'!#REF!="","",'4.담보마스터'!#REF!) -> #REF! | O93: =IF('4.담보마스터'!#REF!="","",'4.담보마스터'!#REF!) -> #REF!
... B100: =IF('4.담보마스터'!#REF!="","",'4.담보마스터'!#REF!) -> #REF! | C100: =IF('4.담보마스터'!#REF!="","",'4.담보마스터'!#REF!) -> #REF! | D100: =IF('4.담보마스터'!#REF!="","",'4.담보마스터'!#REF!) -> #REF! | E100: =IF($C100="","",SUMIFS('5.담보원장'!$G$5:$G$68,'5.담보원장'!$F$5:$F$68,$C100,'5.담보원장'!$B$5:$B$68,E$4)) -> #REF! | F100: =IF($C100="","",SUMIFS('5.담보원장'!$G$5:$G$68,'5.담보원장'!$F$5:$F$68,$C100,'5.담보원장'!$B$5:$B$68,F$4)) -> #REF! | G100: =IF($C100="","",SUMIFS('5.담보원장'!$G$5:$G$68,'5.담보원장'!$F$5:$F$68,$C100,'5.담보원장'!$B$5:$B$68,G$4)) -> #REF! | H100: =IF($C100="","",SUM(E100:G100)) -> #REF! | I100: =IF('4.담보마스터'!#REF!="","",'4.담보마스터'!#REF!) -> #REF! | J100: =IF(OR($C100="",$I100=""),"",$H100-$I100) -> #REF! | K100: =IF($C100="","",IF($I100="","－",IF($H100=0,"미가입",IF($H100>=$I100,"충분","부족")))) -> #REF! | L100: =IF('4.담보마스터'!#REF!="","",'4.담보마스터'!#REF!) -> #REF! | M100: =IF(OR($C100="",$L100=""),"",$H100-$L100) -> #REF! | N100: =IF('4.담보마스터'!#REF!="","",'4.담보마스터'!#REF!) -> #REF! | O100: =IF('4.담보마스터'!#REF!="","",'4.담보마스터'!#REF!) -> #REF!
C102: 범례 | D102: 충분 | E102: 가입금액 ≥ 권장금액 | F102: 부족 | G102: 0 < 가입금액 < 권장금액 | H102: 미가입 | I102: 가입금액 0원 | J102: － | K102: 권장금액 미설정 → 판정 제외
C104: ※ 권장금액 출처: KB손해보험 보장분석 기준(기본담보 37개 / 표준형). ※ 주황색 '2026 시장통용 설계수준'은 KB 권장금액과 별개로, 2026년 8월 현재 시장에서 통용되는 설계 수준을 벤치마크로 표기한 것입니다(가입 권유 아님). 준비상태(충분/부족/미가입) 판정은 KB 권장금액 기준으로만 산출됩니다. ※ 노란색 강조 3개 담보(암주요치료비 · 순환계 통합치료비 · 정액 수술비)는 시트 '7.3대 핵심트렌드' 참고.

Sheet 4.담보마스터
A1: 담보마스터 (구분 · 담보명 · 권장금액 · 최신 트렌드 · 코멘트)
A2: ★ 이 시트가 '3.보장분석(메인)'의 원본입니다. 여기서 담보를 추가·수정·삭제하면 메인 시트에 그대로 반영됩니다.
B4: No | C4: 대분류 | D4: 담보명(표준) | E4: 단위 | F4: 권장금액 (KB기준, 만원) | G4: 2026 시장통용 설계수준(만원) | H4: 최근 담보유형 (2026년 트렌드) | I4: 특이사항 / 코멘트
B5: 1 | C5: 사망 | D5: 일반(종신)사망 | E5: 만원 | F5: 10000 | H5: 종신사망 자체는 정체. 사망보험금 유동화(연금·요양비 전환) 제도 도입으로 활용도 재조명 | I5: 미가입. 손보 종합보험에는 통상 미탑재 — 필요 시 생보 종신/정기로 보완 영역
B6: 2 | C6: 사망 | D6: 질병(정기)사망 | E6: 만원 | F6: 10000 | G6: 10000 | H6: 80세·90세 만기 정기형 질병사망이 주류. 종신형 대비 보험료 1/3 수준 | I6: 미가입 (권장 1억 대비 -1억). 현재 사망보장은 '상해'에만 존재
B7: 3 | C7: 사망 | D7: 재해(정기)사망 | E7: 만원 | H7: 생보 재해사망 개념. 손보는 '상해사망'으로 대체 표기 | I7: 손보 계약이므로 상해사망 행으로 집계
B8: 4 | C8: 사망 | D8: 상해(정기)사망 | E8: 만원 | F8: 20000 | G8: 20000 | H8: 상해사망 + 교통상해사망 + 대중교통이용중 상해사망으로 세분화 설계 | I8: 계약① 기본계약 1,000만 + 상해사망후유장해추가 1억 5,000만 = 1억 6,000만 (권장 2억 대비 -4,000만)
B9: 5 | C9: 수술·입원 | D9: 수술비-질병(1~5종) | E9: 만원 | F9: 50 | G9: 1000 | H9: ★★★2026 3대 핵심 트렌드 ③. 5세대 실손(2026.5.6~)의 비중증 비급여 축소로 정액 수술비의 역할이 커졌습니다. 비중증 비급여 자기부담 30% → 50%, 연간 한도 5,000만 → 1,000만, 통원 1회 20만·병의원 입원 1회 300만 제한 신설. 정액 수술비는 급여·비급여를 따지지 않고 수술확인서만으로 정액 지급되며 반복 청구가 가능해 이 공백을 메웁니다. 1~5종 종수술비(5종 기준 500~1,000만원)가 표준이며, DB손보 '반값 종수술비' 등 판매 경쟁 진행 중 | I9: ★미가입 — 최우선 검토 대상. 계약①은 '16대질병수술 100만원' 한정형만 있어, 16대에 들어가지 않는 수술은 정액 보험금이 0원입니다. 예: 비중증 수술비 300만원 발생 시 5세대 실손 기준 본인부담이 90만원 → 150만원으로 늘어나는데, 신OO님은 2세대 실손이라 실손 쪽 방어는 유리하나 '실손이 아예 안 되는 항목·초과분'은 정액 수술비로만 메울 수 있습니다
B10: 6 | C10: 수술·입원 | D10: 수술비-N대질병 | E10: 만원 | F10: 100 | G10: 500 | H10: N대 범위 확대(16대 → 38대·61대·105대). 다만 최근에는 질병군을 한정하지 않는 1~5종 종수술비 + 질병통합치료비 조합으로 무게중심이 이동 | I10: 계약① 16대질병수술 100만원. 2010년 약관 기준이라 질병군 범위가 좁고, '16대에 해당하는지'를 매번 따져야 하는 한정형 구조입니다
B11: 7 | C11: 수술·입원 | D11: 수술비-재해(상해) | E11: 만원 | F11: 100 | G11: 1000 | H11: 상해 1~5종 종수술비 + 부위별 특정상해수술 병행 설계가 표준. 정액형이라 급여·비급여 구분 없이 지급되며, 5세대 실손 축소의 대안 담보로 함께 거론됨 | I11: 미가입. 계약②는 관절·인대·척추 등 부위별 특정상해수술만 보유해 해당 부위가 아닌 상해수술은 정액 보험금이 0원입니다
B12: 8 | C12: 수술·입원 | D12: 질병통합치료비(검사·시술·수술 포괄) | E12: 만원 | G12: 1000 | H12: ★2026 신설 트렌드 담보. 검사 → 시술 → 수술 → 중증치료를 하나로 묶어 정액 지급하는 확장형 담보. 5세대 실손의 통원·외래 부담 증가에 대응하는 대안으로 수술비와 함께 급부상. 메리츠·KB손보·하나손보 등 판매 | I12: 미가입. 수술 단계만 보는 수술비보다 앞단(검사·시술)까지 포괄해 실손 축소분을 넓게 메우는 구조
B13: 9 | C13: 수술·입원 | D13: 입원일당-질병 | E13: 만원/일 | F13: 3 | G13: 5 | H13: 상급종합병원 가산형·중환자실 가산형 확산. 기본 3만 + 상급종합 추가 3만 구조 | I13: 계약① 2만 (권장 3만 대비 -1만)
B14: 10 | C14: 수술·입원 | D14: 입원일당-N대질병 | E14: 만원/일 | F14: 3 | H14: 4대성인병 → 15대·31대 성인질환으로 대상 확대 | I14: 계약① 4대성인병 1만 + 5대만성질병 1만 = 2만
B15: 11 | C15: 수술·입원 | D15: 입원일당-재해(상해) | E15: 만원/일 | F15: 3 | G15: 5 | H15: 상해입원일당은 1일차부터 지급이 표준화 | I15: 계약① 2만 (권장 3만 대비 -1만). 계약② 교통상해입원일당 1만 별도
B16: 12 | C16: 수술·입원 | D16: 통원일당 | E16: 만원/일 | H16: 실손과 중복되어 최근 축소 추세 | I16: 미가입
B17: 13 | C17: 암 | D17: CI(중대질병)진단자금 | E17: 만원 | H17: CI형은 지급요건이 엄격해 축소. GI형·일반진단비형이 주류 | I17: 미가입
B18: 14 | C18: 암 | D18: 중대한 수술비 | E18: 만원 | H18: CI 계열 담보. 신규 판매 축소 | I18: 미가입
B19: 15 | C19: 암 | D19: 암사망 | E19: 만원 | H19: 암사망 단독 특약은 희소 | I19: 미가입
B20: 16 | C20: 암 | D20: 일반암 진단비 | E20: 만원 | F20: 10000 | G20: 10000 | H20: ★진단금 일시금 → '치료 전 과정 보장'으로 이동. 치료예약 확정 시 선지급(초기 50% → 현재 70%) 구조 확산 | I20: ★계약① 1,000만 (권장 1억 대비 -9,000만) — 전체 담보 중 최대 공백. 2010년 가입분으로 재진단암·고액암 없음
B21: 17 | C21: 암 | D21: 암수술비 | E21: 만원 | F21: 300 | G21: 500 | H21: 로봇수술·중입자치료 등 고액 비급여 수술을 별도 담보로 분리 | I21: 계약① 100만 (권장 300만 대비 -200만)
B22: 18 | C22: 암 | D22: 암입원일당 | E22: 만원/일 | H22: 상급종합병원 암입원일당 가산형 | I22: 계약① 5만
B23: 19 | C23: 암 | D23: 암통원 | E23: 만원/회 | H23: 항암치료의 통원 전환으로 통원일당 수요 증가 | I23: 미가입
B24: 20 | C24: 암 | D24: 고액암(특정암) | E24: 만원 | F24: 5000 | G24: 5000 | H24: 고액암 범위 확대(백혈병·뇌암·골수암·췌장암 등) | I24: 미가입 (-5,000만)
B25: 21 | C25: 암 | D25: 유사암(소액암) | E25: 만원 | F25: 2000 | G25: 2000 | H25: 유사암 한도 상향(1,000만 → 2,000만 이상). 여성 갑상선암 발생 비중이 높아 실효성 큼 | I25: 미가입 (-2,000만). 36세 여성 기준 발생빈도 1순위 영역
B26: 22 | C26: 암 | D26: 표적항암약물허가치료비 | E26: 만원 | F26: 3000 | G26: 5000 | H26: 표적·면역항암 치료비를 별도 담보화, 연간 반복지급형(1년 1회 한) | I26: 미가입 (-3,000만). 타그리소 4주 600만원 등 고액 비급여 대응 불가
B27: 23 | C27: 암 | D27: 항암방사선·약물치료비 | E27: 만원 | G27: 1000 | H27: 회차별 증가형(치료 반복 시 지급액 증액) 신설 — 흥국화재 5대질병 통합치료지원비 최대 1,000만 | I27: 미가입
B28: 24 | C28: 암 | D28: 양성자/호르몬/세기조절 | E28: 만원 | G28: 3000 | H28: 중입자·양성자 치료비 별도 담보화 | I28: 미가입
B29: 25 | C29: 암 | D29: 암주요치료비(비급여 포함) | E29: 만원 | G29: 3000 | H29: ★★★2026 3대 핵심 트렌드 ①. 2024년 2월 삼성화재를 시작으로 전 손보사 확산. '진단 시 한 번'이 아니라 수술·항암약물치료·항암방사선치료 등 실제 치료행위를 받을 때마다 반복 지급. 표적항암제(연 6,000만~1억 2,000만원), 중입자치료(1코스 5,000만~8,000만원), 로봇수술 등 고액 비급여를 직접 보전. 치료예약 확정 시 선지급(초기 50% → 현재 70%). DB손보 최대 1억 2,000만원 / 비급여 암치료비 최대 8,000만원. 현재는 정액형만 판매(2024년 11월 비례형 중단). 시장 통용 설계 3,000만원 내외 | I29: ★미가입 — 최우선 검토 대상. 계약①의 암 담보는 진단 1,000만·수술 100만·입원일당 5만이 전부로, '치료 단계'를 보전하는 담보가 하나도 없습니다. 실손(2세대)이 급여 치료비는 막아주지만 표적항암제·중입자치료 같은 비급여 고액치료는 실손 한도로 감당되지 않습니다. 가입 시 병원등급 기준(종합병원 / 암종합치료기관 / 상급종합병원 중 어디까지 인정하는지)을 반드시 확인해야 합니다
B30: 26 | C30: 특정질환 | D30: 특정질병수술 | E30: 만원 | H30: 16대 → N대 확대. 아래 '수술비-N대질병' 행으로 집계 | I30: 계약① 16대질병수술 100만은 '수술비-N대질병' 행에 집계(중복 방지)
B31: 27 | C31: 특정질환 | D31: 특정질병입원 | E31: 만원/일 | H31: 성인질환 입원일당은 '입원일당-N대질병' 행으로 집계 | I31: 계약① 2만은 '입원일당-N대질병' 행에 집계(중복 방지)
B32: 28 | C32: 특정질환 | D32: 특정질병진단 | E32: 만원 | H32: 생활질환(고혈압·당뇨·고지혈) 통합보장으로 진화 — 흥국화재 7종 세분화, 롯데손보 고당지 3·6·10 | I32: 미가입
B33: 29 | C33: 특정질환 | D33: 뇌혈관질환 수술비 | E33: 만원 | F33: 1000 | G33: 1000 | H33: 수술비 → 주요치료비 → 순환계 통합치료비로 3단계 진화 | I33: 미가입 (-1,000만)
B34: 30 | C34: 특정질환 | D34: 허혈성심장질환 수술비 | E34: 만원 | F34: 1000 | G34: 1000 | H34: 스텐트삽입술·관상동맥우회술 고액화(관상동맥우회술 건당 3,440만원) | I34: 미가입 (-1,000만)
B35: 31 | C35: 특정질환 | D35: 혈전용해제(혈전용해치료비) | E35: 만원 | H35: 단독 담보에서 통합치료비로 흡수되는 추세 | I35: 미가입
B36: 32 | C36: 특정질환 | D36: 뇌·심 주요치료비 / 순환계 통합치료비 | E36: 만원 | G36: 2000 | H36: ★★★2026 3대 핵심 트렌드 ②. 진단비 → 주요치료비 → 순환계 통합치료비의 3단계 진화. ① 대상 확대: 뇌혈관·허혈성심장 2대 질병 → 부정맥·심부전·판막질환 등 순환계 전반(라이나생명 62개 질병코드) ② 지급 사유 확대: MRI·PET·CT 검사, 수술, 혈전용해치료·혈전제거술, 인공호흡기·ECMO, 중환자실 치료, 항응고/항혈소판 주사, 전문재활치료까지 치료 전 과정 ③ 치료 항목별 차등 지급 + 상급종합병원 예약만으로 일부 선지급 ④ 치료기간 소득공백 보전용 생활비 지원 결합. 시장 통용 설계 2,000만원 내외 | I36: ★미가입 — 최우선 검토 대상. 신OO님은 뇌·심장 담보가 진단비 단계조차 0원이라, 최신 통합치료비 구조와는 비교 자체가 성립하지 않는 상태입니다. 60대 사망원인 2위 심장질환(33,715명)·3위 뇌혈관질환(25,420명), 관상동맥우회술 건당 3,440만원·뇌기저부수술 2,035만원을 감안하면 진단비 + 통합치료비를 함께 보는 것이 현재 시장 표준입니다
B37: 33 | C37: 특정질환 | D37: 5대장기이식술 | E37: 만원 | H37: 조혈모세포이식 2,000~3,000만 등 이식 관련 담보 확대 | I37: 미가입
B38: 34 | C38: 뇌 | D38: 뇌혈관질환(100%) | E38: 만원 | F38: 3000 | G38: 3000 | H38: 진단비(기본) + 통합치료비 결합 설계가 표준. 산정특례 진단비 병행 | I38: 미가입 (-3,000만)
B39: 35 | C39: 뇌 | D39: 뇌혈관 산정특례 | E39: 만원 | H39: 산정특례 등록 시 별도 진단비 지급 담보 신설 확산 | I39: 미가입
B40: 36 | C40: 뇌 | D40: 뇌졸중(77%) | E40: 만원 | F40: 3000 | G40: 3000 | H40: 뇌출혈 500~2,000만 / 뇌경색 200~1,000만. 뇌경색 감액 약관 주의 | I40: 미가입 (-3,000만)
B41: 37 | C41: 뇌 | D41: 뇌출혈(16%) | E41: 만원 | F41: 3000 | H41: 후유장해 50% 이상 시 추가 1,000~2,000만 지급형 확산 | I41: 미가입 (-3,000만)
...

Sheet 5.담보원장
A1: 담보원장 (가입설계서 원문 담보 → 표준담보명 매핑)
A2: 가입설계서(보장분석 PDF)의 회사 담보명을 한 줄씩 옮기고 표준담보명으로 매핑했습니다. 이 시트의 금액이 '3.보장분석(메인)'에 합산됩니다.
B4: 계약 No | C4: 상품명 | D4: 구분 | E4: 회사 담보명 | F4: 표준담보명(→담보마스터와 일치) | G4: 가입금액 | H4: 단위 | I4: 비고
B5: 1 | C5: ① Hi1010 (종합) | D5: 정액 | E5: 기본계약 | F5: 상해(정기)사망 | G5: 1000 | H5: 만원
B6: 1 | C6: ① Hi1010 (종합) | D6: 정액 | E6: 상해사망후유장해추가담보 | F6: 상해(정기)사망 | G6: 15000 | H6: 만원
B7: 1 | C7: ① Hi1010 (종합) | D7: 정액 | E7: 기본계약 | F7: 상해후유장해(80%미만) | G7: 1000 | H7: 만원 | I7: 상해후유장해
B8: 1 | C8: ① Hi1010 (종합) | D8: 정액 | E8: 상해사망후유장해추가담보 | F8: 상해후유장해(80%미만) | G8: 15000 | H8: 만원 | I8: 상해후유장해
B9: 1 | C9: ① Hi1010 (종합) | D9: 정액 | E9: 암진단급여금Ⅱ담보 | F9: 일반암 진단비 | G9: 1000 | H9: 만원 | I9: 유사암·고액암 구분 없음
B10: 1 | C10: ① Hi1010 (종합) | D10: 정액 | E10: 골절(치아파절제외)진단위로금담보 | F10: 골절진단비 | G10: 30 | H10: 만원
B11: 1 | C11: ① Hi1010 (종합) | D11: 정액 | E11: 화상진단위로금담보 | F11: 화상진단비 | G11: 50 | H11: 만원
B12: 1 | C12: ① Hi1010 (종합) | D12: 정액 | E12: 16대질병수술급여금담보 | F12: 수술비-N대질병 | G12: 100 | H12: 만원 | I12: 신정원 매핑: 특정질병수술
B13: 1 | C13: ① Hi1010 (종합) | D13: 정액 | E13: 암수술급여금담보 | F13: 암수술비 | G13: 100 | H13: 만원
B14: 1 | C14: ① Hi1010 (종합) | D14: 정액 | E14: 골절수술위로금담보 | F14: 골절·화상 수술비 | G14: 60 | H14: 만원
B15: 1 | C15: ① Hi1010 (종합) | D15: 정액 | E15: 화상수술위로금담보 | F15: 골절·화상 수술비 | G15: 100 | H15: 만원
B16: 1 | C16: ① Hi1010 (종합) | D16: 정액 | E16: 질병입원급여금(1일이상)담보 | F16: 입원일당-질병 | G16: 2 | H16: 만원/일 | I16: 1일 이상
B17: 1 | C17: ① Hi1010 (종합) | D17: 정액 | E17: 4대성인병입원급여금담보 | F17: 입원일당-N대질병 | G17: 1 | H17: 만원/일
B18: 1 | C18: ① Hi1010 (종합) | D18: 정액 | E18: 5대만성질병입원급여금담보 | F18: 입원일당-N대질병 | G18: 1 | H18: 만원/일
B19: 1 | C19: ① Hi1010 (종합) | D19: 정액 | E19: 암입원급여금담보 | F19: 암입원일당 | G19: 5 | H19: 만원/일
B20: 1 | C20: ① Hi1010 (종합) | D20: 정액 | E20: 상해입원급여금(1일이상)담보 | F20: 입원일당-재해(상해) | G20: 2 | H20: 만원/일 | I20: 1일 이상
B21: 1 | C21: ① Hi1010 (종합) | D21: 정액 | E21: 자동차사고부상위로금(비운전자)담보 | F21: 자동차사고부상치료비 | G21: 10 | H21: 만원 | I21: 비운전자
B22: 1 | C22: ① Hi1010 (종합) | D22: 실손 | E22: 상해(일반상해,전체상해) 처방조제료 | F22: 상해통원의료비 | G22: 5 | H22: 만원 | I22: 2세대 실손
B23: 1 | C23: ① Hi1010 (종합) | D23: 실손 | E23: 상해(일반상해,전체상해) 외래의료비 | F23: 상해통원의료비 | G23: 25 | H23: 만원 | I23: 2세대 실손
B24: 1 | C24: ① Hi1010 (종합) | D24: 실손 | E24: 질병(전체질병) 처방조제료 | F24: 질병통원의료비 | G24: 5 | H24: 만원 | I24: 2세대 실손
B25: 1 | C25: ① Hi1010 (종합) | D25: 실손 | E25: 질병(전체질병) 외래의료비 | F25: 질병통원의료비 | G25: 25 | H25: 만원 | I25: 2세대 실손
B26: 1 | C26: ① Hi1010 (종합) | D26: 실손 | E26: 상해+질병 입원의료비 | F26: 상해입원의료비 | G26: 5000 | H26: 만원 | I26: 상해·질병 공통 1개 담보
B27: 1 | C27: ① Hi1010 (종합) | D27: 실손 | E27: 상해+질병 입원의료비 | F27: 질병입원의료비 | G27: 5000 | H27: 만원 | I27: 상해·질병 공통 1개 담보
B28: 1 | C28: ① Hi1010 (종합) | D28: 실손 | E28: 가족생활배상책임 | F28: 가족/일상/자녀 배상책임 | G28: 10000 | H28: 만원 | I28: 자기부담금 2만원
B29: 2 | C29: ② Hi1709 (운전자) | D29: 정액 | E29: 팔및손가락상해후유장해담보 | F29: 특정부위(팔·손가락) 상해후유장해 | G29: 1000 | H29: 만원 | I29: 신정원 매핑: 특정교통상해사망
B30: 2 | C30: ② Hi1709 (운전자) | D30: 정액 | E30: 골절진단(치아파절제외)담보 | F30: 골절진단비 | G30: 50 | H30: 만원
B31: 2 | C31: ② Hi1709 (운전자) | D31: 정액 | E31: 관절(무릎·고관절)수술담보 | F31: 특정상해수술(부위별 합계) | G31: 30 | H31: 만원
B32: 2 | C32: ② Hi1709 (운전자) | D32: 정액 | E32: 뇌·내장손상수술담보 | F32: 특정상해수술(부위별 합계) | G32: 100 | H32: 만원
B33: 2 | C33: ② Hi1709 (운전자) | D33: 정액 | E33: 무릎인대파열/연골손상수술담보 | F33: 특정상해수술(부위별 합계) | G33: 30 | H33: 만원
B34: 2 | C34: ② Hi1709 (운전자) | D34: 정액 | E34: 아킬레스힘줄손상수술담보 | F34: 특정상해수술(부위별 합계) | G34: 50 | H34: 만원
B35: 2 | C35: ② Hi1709 (운전자) | D35: 정액 | E35: 안면부상해흉터성형수술담보 | F35: 특정상해수술(부위별 합계) | G35: 200 | H35: 만원
B36: 2 | C36: ② Hi1709 (운전자) | D36: 정액 | E36: 외상성척추손상수술담보 | F36: 특정상해수술(부위별 합계) | G36: 50 | H36: 만원
B37: 2 | C37: ② Hi1709 (운전자) | D37: 정액 | E37: 인공관절수술담보 | F37: 특정상해수술(부위별 합계) | G37: 100 | H37: 만원
B38: 2 | C38: ② Hi1709 (운전자) | D38: 정액 | E38: 교통상해입원일당(1~180일, 자동차운전중)담보 | F38: 교통상해입원일당 | G38: 1 | H38: 만원/일
B39: 2 | C39: ② Hi1709 (운전자) | D39: 정액 | E39: 자동차사고부상(운전자)담보 | F39: 자동차사고부상치료비 | G39: 20 | H39: 만원 | I39: 운전자
B40: 2 | C40: ② Hi1709 (운전자) | D40: 정액 | E40: 자동차사고치아보철치료비담보 | F40: 보철치료비 | G40: 5 | H40: 만원
B41: 2 | C41: ② Hi1709 (운전자) | D41: 정액 | E41: 중증자동차사고부상(운전자)담보 | F41: 중증자동차사고부상 | G41: 1000 | H41: 만원
...

Sheet 6.실손분석
A1: 실손의료비 분석 — 세대 판정 및 전환 검토
A2: 가입 시기를 '실손보험 변천사' 기준에 대조해 세대를 판정했습니다. 전환 여부는 중립적으로 비교만 제시합니다.
B4: 1) 신OO님 실손 세대 판정
B5: 가입 계약 | C5: ① 무배당하이라이프퍼펙트패키지보험(Hi1010)2종 (현대해상)
B6: 가입일 | C6: 2010-12-23
B7: 판정 세대 | C7: ★ 2세대 실손 — 표준화 이전기 (2009년 10월 ~ 2013년 3월 구간)
B8: 자기부담금 | C8: 입원 10% / 통원 1~2만원 정액 공제
B9: 보장 한도 | C9: 입원 5,000만원 / 통원 30만원 (외래 25만 + 처방조제 5만)
B10: 갱신 · 재가입 | C10: 갱신 3년 주기 / 재가입 조건 없음 → 가입 당시 약관이 만기까지 유지
B11: 보험기간 | C11: 2010-12-23 ~ 2090-12-23 (100세 만기)
B12: 3대 비급여 | C12: 별도 특약 분리 없음 → 도수치료·비급여 주사·비급여 MRI가 기본 보장에 포함되며 자기부담 10% 적용
B14: 2) 실손의료보험 세대별 변천사 (전체 비교)
B15: 세대 구분 | C15: 가입 시기 | D15: 보장 내용(자기부담금) | E15: 가입 한도 | F15: 갱신 / 재가입 | G15: 주요 특징 및 변화 | H15: 비고
B16: 1세대 (구실손) | C16: ~ 2009년 9월 | D16: 입원: 자기부담 없음(100%) 통원: 5천원 공제 | E16: 입원 3천만~1억 통원 10만~30만 | F16: 갱신 3~5년 / 재가입 없음 | G16: [표준화 이전] 자기부담금이 없어 보장성 최고, 갱신 시 보험료 인상 폭 큼
B17: 2세대 (표준화 이전기) | C17: 2009년 10월 ~ 2013년 3월 | D17: 입원: 10% 자기부담 통원: 1~2만원 공제 | E17: 입원 5,000만 통원 30만 | F17: 갱신 3년 / 재가입 없음 | G17: [표준화 도입] 보험사별 보장 통일, 가입 당시 조건이 만기까지 유지 | H17: ★신OO님 해당 (2010-12-23)
B18: 2세대 (표준화 이후기) | C18: 2013년 4월 ~ 2017년 3월 | D18: 입원: 10~20% 자기부담 통원: 1~2만원 공제 | E18: 입원 5,000만 통원 30만 | F18: 갱신 1년 / 재가입 15년 | G18: [15년 재가입 신설] 15년 후 새 약관 기준으로 재가입 필요
B19: 3세대 (착한실손) | C19: 2017년 4월 ~ 2021년 6월 | D19: 급여 10~20% 비급여 20% 3대비급여 특약 30% | E19: 입원 5,000만 통원 30만 | F19: 갱신 1년 / 재가입 15년 | G19: [기본+특약 분리] 도수치료·MRI·비급여주사 특약 분리, 무사고 할인 도입
B20: 4세대 | C20: 2021년 7월 ~ 2026년 4월 | D20: 급여 20% 비급여 30% | E20: 급여/비급여 각각 입·통원 합산 연 5,000만 | F20: 갱신 1년 / 재가입 5년 | G20: [보험료 차등제] 비급여 이용량에 따라 할증·할인, 재가입 주기 5년
B21: 5세대 | C21: 2026년 5월 6일 ~ 현재 | D21: 급여: 입원 20%, 통원은 건보 본인부담률 연동 중증비급여 30%(연 상한 500만) 비중증비급여 50% | E21: 급여 연 5,000만 중증비급여 연 5,000만 비중증비급여 연 1,000만 | F21: 갱신 1년 / 재가입 5년 | G21: [중증/비중증 분리] 중증 보장 강화, 비중증 비급여는 선택·제한 구조
B23: 3) 2세대 유지 vs 5세대 전환 — 중립 비교
B24: 비교 항목 | C24: 현재 유지 (2세대 · 표준화 이전기) | D24: 5세대로 전환할 경우 | F24: 판단 시 확인할 점
B25: 보험료 | C25: 상대적으로 높음. 갱신 3년 주기로 인상폭이 한 번에 크게 체감됨 | D25: 4세대 대비 30~50% 저렴. 2세대 대비 체감 절감폭은 더 큼 | F25: 지금 월 56,300원은 실손 외 정액담보가 포함된 금액이라 실손만 분리한 보험료 확인 필요
B26: 급여 자기부담 | C26: 입원 10% (가장 낮은 수준) | D26: 입원 20%, 통원은 건강보험 본인부담률 연동 | F26: 상급종합병원을 자주 이용하면 5세대 통원 부담이 커짐
B27: 비급여 자기부담 | C27: 10% (3대 비급여 특약 분리 없음) | D27: 중증 비급여 30%(연 상한 500만원) / 비중증 비급여 50% | F27: 도수치료·비급여 주사·MRI 이용 빈도가 판단의 핵심
B28: 비급여 한도 | C28: 입원 5,000만원 한도 내 포괄 | D28: 비중증 비급여 연 1,000만원, 통원 1회 20만원, 병의원 입원 1회 300만원 | F28: 비중증 한도 축소가 가장 큰 체감 변화
B29: 중증 보장 | C29: 일반 한도 내 보장 (별도 상한 없음) | D29: 암·뇌혈관 등 중증 비급여는 연간 자기부담 상한 500만원으로 방어력 강화 | F29: 고액 중증 치료만 놓고 보면 5세대가 유리한 구간이 있음
B30: 재가입 · 약관 변경 | C30: ★재가입 조건 없음 → 2090년까지 현재 약관 유지 | D30: 5년마다 재가입, 그때그때의 새 약관이 적용됨 | F30: '조건이 바뀌지 않는다'는 점이 2세대의 가장 큰 자산 — 전환하면 되돌릴 수 없음
B31: 신규 보장 | C31: 임신·출산, 발달장애 급여 의료비 미보장 | D31: 임신·출산 관련 의료비(산전검사·분만 등), 발달장애 급여 의료비 신규 포함 | F31: 만 36세 여성으로 출산 계획이 있다면 실질 가치가 있는 항목
B32: 전환 인센티브 | C32: 해당 없음 | D32: 2026년 11월 시행 예정 — 1·2세대 초기 가입자 대상 선택형 할인 특약 또는 계약전환 할인(전환 시 3년간 50% 할인) 중 선택 | F32: 제도 시행 전이므로 확정 조건을 반드시 확인한 뒤 판단
B34: 정리 | C34: 판단 기준은 '병원 이용 목적'입니다. ① 도수치료·비급여 주사 등 일상적 통증 치료를 자주 이용한다면 → 2세대 유지가 유리합니다. ② 병원을 거의 가지 않고 고액 중증 질환 대비가 목적이라면 → 보험료가 크게 낮아지는 5세대 전환도 선택지가 됩니다. ③ 다만 2세대의 '재가입 없음(약관 고정)'은 한 번 포기하면 복구할 수 없다는 점을 반드시 감안하시기 바랍니다. ④ 2026년 11월 시행 예정인 1·2세대 대상 할인 제도의 확정 내용을 본 뒤 판단하시는 것을 권합니다. ▶ 다만 실손 세대와 무관하게, 실손이 애초에 보상하지 않는 항목과 한도 초과분은 정액 수술비로만 메울 수 있습니다. 5세대 전환을 검토한다면 정액 수술비·질병통합치료비 보완이 사실상 전제 조건이 됩니다. 시트 '7.3대핵심트렌드' ③ 참고.

Sheet 7.3대핵심트렌드
A1: 2026년 3대 핵심 트렌드 — 암 주요치료비 · 순환계 주요치료비 · 정액 수술보험금
A2: 세 담보군은 서로 독립된 유행이 아니라 '진단금 중심 → 치료비 중심'이라는 하나의 흐름입니다. 신OO님 계약과의 간극을 항목별로 정리했습니다.
B4: 관통하는 흐름
B5: 과거 보험은 '병에 걸린 사실'에 돈을 줬습니다(진단금). 지금 보험은 '치료를 받는 행위'에 돈을 줍니다(치료비). 이 변화의 배경은 두 가지입니다. ① 치료 기술이 고액 비급여(표적항암제·중입자치료·로봇수술·ECMO)로 옮겨가면서 진단금 한 번으로는 치료비를 감당할 수 없게 됐습니다. ② 2026년 5월 5세대 실손이 비중증 비급여 보장을 대폭 줄이면서, 실손이 메워주던 자리를 정액 담보가 대신 메워야 하게 됐습니다. 신OO님 계약은 ①의 결과물이 하나도 없고(암·뇌·심장 치료비 담보 전무), ②에 대해서는 2세대 실손 덕분에 '실손 쪽은 유리하지만 정액 수술비 쪽은 비어 있는' 절반의 상태입니다.
B7: 트렌드 | C7: 항목 | D7: 시장의 현재 모습 (2026년 8월) | E7: 신OO님 계약의 현재 상태 | F7: 근거 / 출처
B8: ① 암 주요치료비 | C8: 무엇인가 | D8: 암 진단 시 한 번 주는 진단금과 별개로, 수술 · 항암약물치료 · 항암방사선치료 등 실제 치료를 받을 때마다 반복 지급하는 담보. 2024년 2월 삼성화재를 시작으로 전 손보사로 확산됐습니다. | E8: 해당 담보 없음. 계약①(2010년 가입)의 암 관련 담보는 진단 1,000만 · 암수술 100만 · 암입원일당 5만이 전부입니다. | F8: 다자비 / 뱅크샐러드
C9: 왜 필요한가 | D9: 보장 대상이 고액 비급여입니다. 표적항암제 연 6,000만~1억 2,000만원, 중입자치료 1코스 5,000만~8,000만원, 타그리소 4주 600만원 · 1년 7,000만원, 엔허투 1회 투약 500만~800만원. 실손은 통원 한도가 20~30만원이라 이 금액대를 감당하지 못합니다. | E9: ★2세대 실손이 급여 치료비는 잘 막아주지만, 비급여 항암제는 실손 한도 안에서 처리되지 않습니다. 진단금 1,000만원으로는 표적항암제 두 달치도 되지 않습니다. | F9: 약학정보원 2023 / 뱅크샐러드
C10: 어떻게 지급되나 | D10: ① 정액형만 판매(2024년 11월부터 비례형 중단) ② 치료예약 확정 시 선지급 — 초기 50%에서 현재 70%까지 확대 ③ 연간 합산형 / 행위별 개별한도형 / 구간형(계단식)으로 나뉨 ④ DB손보 암주요치료비 최대 1억 2,000만원, 비급여 암치료비 최대 8,000만원 | E10: 미보유. 시장 통용 설계수준은 3,000만원 내외입니다. | F10: 뱅크샐러드 / 보험신보
C11: 확인할 점 | D11: ★병원등급 기준이 상품마다 다릅니다. 종합병원까지 인정하는지, 암종합치료기관까지인지, 상급종합병원만인지에 따라 실제 지급 여부가 갈립니다. 구간형은 구간 경계에 못 미치면 지급액이 크게 줄어듭니다. | E11: 가입 검토 시 반드시 약관에서 확인해야 할 항목입니다. | F11: 뱅크샐러드
B13: ② 순환계 주요치료비 | C13: 무엇인가 | D13: 뇌·심장 보장이 '진단비 → 주요치료비 → 순환계 통합치료비'로 3단계 진화했습니다. MRI·PET·CT 검사, 수술, 혈전용해치료·혈전제거술, 인공호흡기·ECMO, 중환자실 치료, 항응고·항혈소판 주사, 전문재활치료까지 치료 전 과정을 하나로 묶어 항목별 차등 지급합니다. | E13: ★해당 담보 없음. 그 이전 단계인 진단비조차 0원입니다. 뇌혈관질환 · 뇌졸중 · 뇌출혈 · 허혈성심장질환 · 급성심근경색 전부 미가입입니다. | F13: 다자비 Market Trend ②
C14: 대상이 넓어졌다 | D14: 기존 2대 질병 주요치료비는 뇌혈관질환 + 허혈성심장질환에 국한됐지만, 순환계 주요치료비는 부정맥 · 심부전 · 판막질환 등 순환계 질환 전반을 포괄합니다. 라이나생명은 순환계 62개 질병코드를 담았습니다. | E14: 신OO님은 좁은 쪽(2대 질병 진단비)조차 없어, 넓어진 시장 기준과 비교 자체가 성립하지 않습니다. | F14: 다자비 Market Trend ②
C15: 왜 필요한가 | D15: 60대 사망원인 2위 심장질환(33,715명) · 3위 뇌혈관질환(25,420명). 2022년 수술 건당 진료비 1위 관상동맥우회술 3,440만원(연평균 +5.7%), 2위 심장수술 3,436만원, 3위 뇌기저부수술 2,035만원(+8.4%), 9위 스텐트삽입술 1,060만원. 상위 10개 중 6개가 순환계 수술입니다. | E15: 이 금액이 발생하면 현재는 2세대 실손(자기부담 10%)으로만 대응하게 되며, 치료 기간 중 소득 공백을 메울 정액 보험금은 전혀 없습니다. | F15: 2021 주요수술통계연보 / 국민건강보험
C16: 최신 지급 구조 | D16: ① 치료 항목별 차등 지급 ② 상급종합병원 예약만으로 일부 선지급 ③ 치료기간 생활비 지원 결합 ④ 산정특례 등록 시 별도 진단비 지급 담보 병행 | E16: 미보유. 시장 통용 설계수준은 2,000만원 내외이며, 진단비(3,000만원 수준)와 함께 구성하는 것이 현재 표준입니다. | F16: 다자비 / 보험신보
B18: ③ 정액 수술보험금 | C18: 왜 지금 중요한가 | D18: ★2026년 5월 6일 시행된 5세대 실손이 비중증 비급여 보장을 대폭 축소했습니다. 자기부담률 30% → 50%, 연간 한도 5,000만원 → 1,000만원, 통원 1회 20만원 · 병의원 입원 1회 300만원 제한 신설. 도수치료 · 비급여 주사 · MRI는 아예 지급 제외 방안이 추진 중입니다. | E18: 신OO님은 2세대라 이 축소의 직접 영향은 받지 않습니다. 다만 '실손이 애초에 보상하지 않는 항목'과 '실손 한도 초과분'은 세대와 무관하게 정액 수술비로만 메울 수 있습니다. | F18: 보험저널 / KB의 생각
C19: 숫자로 보면 | D19: 비중증 수술비 300만원이 발생할 때 가입자 부담은 기존 90만원 → 150만원으로 늘어납니다(5세대 기준). 이 차액을 메우는 것이 정액 수술비의 역할입니다. | E19: 2세대 유지 시 신OO님 부담은 30만원 수준이라 유리합니다. 그러나 계약①의 정액 수술 담보는 '16대질병수술 100만원' 한정형뿐이라, 16대에 들어가지 않는 수술은 정액 보험금이 0원입니다. | F19: 보험저널
C20: 어떤 담보로 메우나 | D20: ① 1~5종 종수술비 — 급여 · 비급여를 따지지 않고 수술확인서만으로 정액 지급, 반복 청구 가능(5종 기준 500~1,000만원) ② 질병통합치료비 — 검사 · 시술 · 수술 · 중증치료를 하나로 묶은 확장형(메리츠 · KB손보 · 하나손보 등) ③ 상해 1~5종 종수술비 ④ 근골격계 비급여 · 비급여 주사제 정액담보 | E20: ①②③ 모두 미보유. 계약②의 부위별 특정상해수술 7종은 해당 부위가 아니면 지급되지 않는 한정형입니다. | F20: 보험저널 / 시장 표준
C21: 시장 동향 | D21: 5세대 출시를 앞두고 정액형 담보 수요가 몰렸고, DB손보는 '반값 종수술비' 판매 종료를 4월까지 연기하는 등 브릿지 전략을 폈습니다. 업계는 정액 반복보장 구조가 '설명이 쉽고 설득력이 높다'고 평가합니다. | E21: 정액 수술비는 비갱신형으로 준비하는 것이 일반적입니다. 계약①(비갱신 25년납)과 성격이 맞습니다. | F21: 보험저널
B23: 한 줄 정리 | C23: 신OO님의 보장은 '2010년의 보험'입니다. 2010년 기준으로는 나쁘지 않은 설계였고, 특히 2세대 실손은 지금도 최상급입니다. 다만 그 이후 15년간 보험이 진단금에서 치료비로 옮겨가는 동안 계약은 그대로였습니다. 암 주요치료비 · 순환계 주요치료비 · 정액 수술비 세 가지는 '더 좋은 상품으로 갈아타는' 문제가 아니라, 지금 계약에 없는 종류의 보장을 더하는 문제입니다. 기존 계약, 특히 계약①의 2세대 실손은 그대로 두는 것이 전제입니다.

Sheet 8.최근담보유형
A1: 담보별 최근(2026년) 담보유형 트렌드 비교
A2: 2026년 8월 기준 시장에서 판매 중인 담보 구성과 신OO님 보유 담보를 비교했습니다. 근거 출처는 하단 참고.
B4: 담보군 | C4: 과거(2010~2019년 가입 시점) 구조 | D4: 2026년 현재 담보유형 | E4: 신OO님 계약과의 차이 | F4: 출처
B5: 암 | C5: 암 진단 시 일시금 지급이 전부. 유사암·고액암 구분 없음 | D5: 진단금 → '치료 전 과정 보장'으로 이동. 암주요치료비(수술·항암약물·방사선 등 실제 치료행위 연동), 비급여 암치료비, 표적·면역·중입자 치료비, 치료 예약 확정 시 선지급(50%→70%), 회차별 증가형 치료지원비 | E5: 계약①은 2010년 약관으로 일반암 1,000만·암수술 100만·암입원일당 5만이 전부. 유사암·고액암·재진단암·항암치료비·주요치료비 전 항목 부재 — 최근 15년간 신설 담보군 전체가 공백 | F5: 다자비 보험AI뉴스 / 보험신보
B6: 뇌 · 심장 | C6: 뇌졸중·급성심근경색 진단비 중심 (좁은 범위) | D6: ① 진단비 범위 상향(뇌졸중→뇌혈관질환, 급심→허혈성→심혈관질환) ② 주요치료비(수술·혈전용해) ③ ★순환계 통합치료비 — MRI·PET·CT 검사, 수술·혈전용해/제거술, 인공호흡기·ECMO, 항응고/항혈소판 주사, 전문재활치료까지 전 과정 포괄 ④ 산정특례 진단비 신설 | E6: 계약①②③ 모두 뇌·심장 담보가 단 하나도 없습니다. 진단비 단계조차 미가입이라 최신 통합치료비 구조와는 비교 자체가 어려운 상태 | F6: 다자비 보험AI뉴스
B7: 간병 · 치매 | C7: 장기요양 담보 자체가 드물었고, 있어도 1~2등급 한정 | D7: ① 장기요양 1~5등급·인지지원등급까지 확대, 등급별 차등지급 ② CDR 척도별 치매진단비(CDR1 500~1,000만 / CDR2 1,000~2,000만 / CDR3 2,000~3,000만) ③ 간병인사용일당 7~10만원/일 이상 권장(실제 간병비 10~15만원/일) ④ 신경인지기능 종합검사비 지원, 아밀로이드 베타 표적치료제 회차별 치료비 | E7: 전 계약 미가입. 간병도우미료 소비자물가가 전년 대비 13% 상승 중이라 시간이 갈수록 공백 체감이 커지는 영역 | F7: 베이비빌리 / 보험신보
B8: 수술 · 입원 | C8: 16대·4대 등 한정 질병군 수술·입원 담보 | D8: ① 질병·상해 1~5종 종수술비(5종 500~1,000만) ② N대 질병 범위 확대(16대→38대·61대·105대) ③ 상급종합병원·중환자실 입원일당 가산형 ④ 로봇수술 등 고액 비급여 수술 별도 담보화 | E8: 계약① 16대질병수술 100만·입원일당 2만은 2010년 기준. 일반 질병수술비·상해수술비가 없어 '수술을 했는데 16대에 안 들어가면 못 받는' 구조. 입원일당도 현 권장 3만 대비 2만 | F8: 교보생명 뉴스룸 / 시장 표준
B9: 실손 | C9: 2세대 표준화 실손 — 자기부담 10%, 3대 비급여 특약 분리 없음, 재가입 없음 | D9: 5세대(2026.5.6~) — 급여/중증비급여/비중증비급여 3분할, 자기부담 20%/30%/50%, 비중증 비급여 연 1,000만 한도, 통원 1회 20만 제한, 재가입 5년 | E9: ★유일하게 신OO님이 '앞서 있는' 담보입니다. 세대가 내려갈수록 자기부담은 높아지고 한도는 줄었으므로, 2세대 유지는 그 자체로 자산입니다. 상세 비교는 시트 '6.실손분석' 참고 | F9: KB의 생각 / 실손보험 변천사
B10: 운전자 | C10: 벌금 2,000만·교통사고처리지원금 3,000만·변호사선임비용 500만이 통상 수준(2017년 기준) | D10: ① 벌금 대인 3,000만(스쿨존 포함)·대물 500만 ② 교통사고처리지원금 2억~2.5억 권장 ③ ★변호사선임비용 2026년 개정: 심급별 500만·총 1,500만 + 자기부담금 50% 신설 ④ 자동차사고부상치료비 1~14급 차등(14급 경미 부상도 약 30만) ⑤ 12대 중과실에 어린이집·유치원 시설 내 사고 추가 | E10: 계약②는 2017년 약관이라 변호사비 자기부담금 50%가 없는 유리한 조건입니다. 다만 교통사고처리지원금 3,000만은 현 합의금 시세(2억 권장) 대비 크게 부족하고, 대물벌금 담보가 없습니다 | F10: TILNOTE 2026 운전자보험 개정 정리
B11: 생활 · 만성질환 | C11: 만성질환은 인수 거절 사유이거나 담보 자체가 없었음 | D11: ① 고혈압·당뇨·고지혈 통합보장(흥국화재 7종 세분화, 롯데손보 고당지 3·6·10) 및 무질환자 최대 10% 할인 ② 유병자 인수기준 완화(입원·수술 확인기간 5년→2년) ③ 헬스케어 플랫폼 연계 현물보장(연속혈당측정기·인바디·간호사 동행) ④ 무사고 시 건강지원금 환급형 | E11: 전 계약 미가입. 36세 현재는 급하지 않으나, 향후 만성질환 발생 후에는 가입이 어려워지는 담보군입니다 | F11: 보험신보 2026 상반기 상품 트렌드
B12: 사망 · 후유장해 | C12: 상해사망·상해후유장해 중심(손보 종합보험 표준) | D12: ① 질병사망은 80·90세 만기 정기형으로 저렴하게 보완하는 설계가 일반화 ② 질병 3% 이상 후유장해 비례보상 확대 ③ 사망보험금 유동화(연금·요양비 전환) 제도 논의 | E12: 계약① 상해사망 1억 6,000만·상해후유장해 1억 6,000만은 권장 대비 양호하나, 질병사망 0원 / 질병후유장해 0원으로 '질병' 쪽이 통째로 비어 있습니다 | F12: 보험신보 / 시장 표준
B14: 출처
B15: 구분 | C15: 자료 | D15: 링크
B16: 보장분석 원자료 | C16: 20260813_신O하님_보장분석.pdf (KB손해보험 경기강원GA사업단, 한국신용정보원 집적 계약정보 기반) | D16: -
B17: 포맷 기준 | C17: 보장분석24.xlsx ('김수진 가족' 시트 구분 체계) | D17: -
B18: 실손 세대 구분 | C18: 실손보험 변천사.docx | D18: -
B19: 2026 상반기 상품 트렌드 | C19: 보험신보 '2026 상반기 패러다임을 바꾼 보험상품' | D19: https://www.insweek.co.kr/news/articleView.html?idxno=71493
B20: 순환계 통합치료비 | C20: 다자비 보험AI뉴스 '순환계질환, 주요치료비 넘어 통합치료비로' | D20: https://dazabi.com/insurance_magazine/article.php?id=25883
B21: 암보험 트렌드 | C21: 다자비 보험AI뉴스 '암보험, 이제는 진단금보다 치료 전 과정 보장으로' | D21: https://dazabi.com/insurance_magazine/article.php?id=20601
B22: 5세대 실손 | C22: KB의 생각 '5세대 실손보험 출시, 달라진 점과 전환하기 전 확인 사항' | D22: https://kbthink.com/insurance/trend/5th-generation.html
B23: 운전자보험 2026 개정 | C23: TILNOTE '2026 운전자보험 필수 특약 추천 개정 핵심 정리' | D23: https://tilnote.io/en/pages/69db02566b890bb9dc86f13e
B24: 간병보험 트렌드 | C24: 베이비빌리 '간병보험 완전정리 2026' | D24: https://villagebaby.kr/care/간병보험-완전정리/
B25: 5세대 실손 → 수술비 대안 | C25: 보험저널 '5세대 실손 비중증 환자 부담 커진다… 수술비·질병통합치료비 대안 급부상' | D25: https://www.insjournal.co.kr/news/articleView.html?idxno=30554
B26: 정액형 담보 수요 | C26: 보험저널 '5세대 실손보험 출시 앞두고 … 급여·비급여 안 따지는 정액형 담보 수요 몰린다' | D26: https://www.insjournal.co.kr/news/articleView.html?idxno=26340
... B29: 순환계 주요치료비 | C29: 다자비 보험AI뉴스 'Market Trend ② 심·뇌 보장, 2대 질병 넘어 순환계 주요치료비로' | D29: https://dazabi.com/insurance_magazine/article.php?id=20298

Sheet 9.특이사항
A1: 특이사항 정리
A2: 계약·담보·기간 관점에서 반드시 짚어야 할 항목입니다.
B4: 구분 | C4: 항목 | D4: 내용 | E4: 관련 계약 | F4: 확인 시점
B5: 유지가치 | C5: 2세대 실손 (2010-12-23) | D5: 자기부담 10%, 3대 비급여 특약 분리 없음, 재가입 조건 없이 2090-12-23(100세)까지 현재 약관 유지. 5세대(자기부담 20~50%, 비중증 연 1,000만 한도)와 비교하면 보유 계약 중 대체 불가능한 자산입니다. | E5: 계약① | F5: 상시
B6: 유지가치 | C6: 운전자보험 구약관 | D6: 2017-11-20 가입분으로 2026년 개정(변호사선임비용 심급별 500만·총 1,500만 + 자기부담금 50%) 적용을 받지 않습니다. 단 절대 한도(500만원)는 낮으므로, 해지가 아니라 '추가 보완'이 맞는 접근입니다. | E6: 계약② | F6: 상시
B7: 만기 임박 | C7: 자동차보험 만기 2026-08-19 | D7: KB다이렉트개인용(무보험차상해 5억 / 다른 자동차 운전담보 1,000만) 보험기간이 2025-08-19 ~ 2026-08-19로, 기준일(2026-08-13) 기준 6일 뒤 만기입니다. 갱신 처리 여부를 즉시 확인해야 합니다. | E7: 별도(KB손보) | F7: ★즉시
B8: 만기 예정 | C8: 치아보험 2034-10-01 만기 | D8: 만 44세 만기로 3건 중 가장 먼저 종료됩니다. 만기 시 치아보존 40만·기타 치과치료비뿐 아니라 보철치료비 200만원이 함께 소멸해, 보철치료비 합계가 205만 → 5만원으로 급감합니다. | E8: 계약③ | F8: 2034년
B9: 보험료 | C9: 치아보험 갱신 인상 | D9: 월 50,320원으로 전체 보험료(119,550원)의 42%를 차지하는데, 갱신형이라 갱신 시마다 인상됩니다. 보장 대비 보험료 비중이 적정한지 갱신 시점마다 점검이 필요합니다. | E9: 계약③ | F9: 갱신 주기마다
B10: 보장 공백 | C10: 생존 담보 부재 | D10: 뇌혈관·뇌졸중·뇌출혈·허혈성심장질환·급성심근경색 진단비가 전부 0원, 간병·치매도 전부 0원입니다. 일반암도 1,000만원으로 권장(1억) 대비 -9,000만원입니다. | E10: 전 계약 | F10: 상시
B11: 보장 공백 | C11: 질병 사망 · 질병 후유장해 0원 | D11: 상해사망 1억 6,000만·상해후유장해 1억 6,000만은 확보되어 있으나 질병 쪽은 전무합니다. 손해보험 종합보험의 전형적인 편중 구조입니다. | E11: 전 계약 | F11: 상시
B12: 판정 주의 | C12: 3대 비급여실손 '미가입' 표시 | D12: 권장 350만원 대비 가입 0원으로 표시되지만, 2세대 실손은 3대 비급여가 기본 보장에 포함(자기부담 10%)되어 있습니다. 실질적인 공백이 아니므로 판정 결과를 그대로 해석하면 안 됩니다. | E12: 계약① | F12: 해석 시
B13: 집계 주의 | C13: 중복 집계 방지 처리 | D13: ① 계약①의 '16대질병수술 100만'은 신정원 매핑상 '특정질병수술'이나, 보장분석24 포맷의 '수술비-N대질병' 행에만 집계했습니다. ② 계약①의 '상해+질병 입원의료비 5,000만'은 하나의 담보이나 상해입원·질병입원 두 행에 각각 표기했습니다(원 보장분석 PDF와 동일 방식). ③ 계약②의 부위별 특정상해수술 7종은 1사고 합산지급이 아니므로 권장금액 판정에서 제외했습니다. | E13: 전 계약 | F13: 해석 시
B14: 자료 한계 | C14: 신용정보원 조회 기준 | D14: 본 분석은 한국신용정보원에 집적된 계약정보(손보 2002년 12월 이후, 생보 2000년 4월 이후, 공제 2009년 10월 이후 계약 건만 조회) 기반이며 정상계약만 포함합니다. 실효·해지 건과 단체보험은 빠져 있어 실제 가입 현황과 차이가 있을 수 있습니다. | E14: 전체 | F14: 해석 시
C16: 자동차보험 조회 내역 (신용정보원 · 별도 계약)
B17: 회사 | C17: 상품 / 담보유형 | D17: 담보명 | E17: 보험기간 | F17: 가입금액
B18: KB손보 | C18: KB다이렉트개인용 / 무보험차상해 | D18: 무보험차에 의한 상해(개인용,업무용,이륜차) | E18: 2025-08-19 ~ 2026-08-19 | F18: 5억
B19: KB손보 | C19: KB다이렉트개인용 / 다른자동차상해 | D19: 다른 자동차 운전담보 | E19: 2025-08-19 ~ 2026-08-19 | F19: 1,000만
